Workbook

Sheet Read Me
A1: FleetPods Alberta Phase 1 - PPP Financial Model (BASIC / WORKING VERSION)
A4: Built to maximize institutional credibility using this engagement's available inputs and standard Canadian project-finance conventions. See below for exactly what was added.
A7: SITE-LEVEL DETAIL
A8: All 8 sites are modelled individually (Site Detail tab).
A9: Capex is the Business Case's exact per-site figure. Stall/pod counts and opex were scaled from the typology averages by each site's capex share (e.g. a site 8% above its typology's average capex gets 8% more stalls/pods/opex) this is this model's own estimate, not client-confirmed per-site data (none exists yet), and should be replaced once real site-level surveys exist.
A13: SENIOR + MEZZANINE DEBT
A14: Debt is split 55% senior (6.0%) / 15% mezzanine (11.5%, senior + 550bps, per the Business Case's stated mezzanine pricing convention) / 30% equity, blended to ~7.2%. This is a BLENDED-RATE simplification (both tranches amortise on the same schedule) rather than two fully separate schedules with different tenors/priorities a full build would size and amortise each tranche separately once real lenders are engaged.
A20: DSRA, WORKING CAPITAL, TERMINAL VALUE
A21: DSRA: 6 months of debt service, funded by an additional equity call at Year 4, released back to equity at the end of the debt tenor (Year 26).
A23: Working capital: 5% of annual opex, built up from first year of operations and fully released in Year 30, flowing through CFADS.
A25: Terminal value: 6.0x final-year EBITDA, paid to equity in Year 30 a standard simplified proxy for the network's ongoing value beyond the 30-year concession (no formal residual valuationhas been done; this multiple is this model's own placeholder assumption, flagged for review).
A29: SCULPTED DEBT REPAYMENT
... A67: Red = flagged/solved cell needing validation

Sheet Executive Summary
A1: EXECUTIVE SUMMARY : FleetPods Alberta Phase 1 Financial Model
A4: Overview
A5: FleetPods proposes an 8-site truck parking, rest-pod, and driver-service network across Alberta's principal freight corridors, with a total program capital cost of CAD 155.1M (2026 real terms). The network combines one flagship Mega Hub (Calgary-Airdrie), three Regional Hubs (West Edmonton-Acheson, Red Deer, Fort McMurray-Suncor), and four lighter Infill Gateway Hubs (Seebe-Cochrane, Brooks, Medicine Hat, Whitecourt-Fox Creek), financed on a 70% debt / 30% equity structure over a 30-year concession.
A10: The Core Question: Can User Fees Alone Make This Bankable?
A11: No. This model tests two funding structures side by side and finds that commercial revenue (parking, recovery pods, fleet subscriptions, digital platform, ancillary services) cannot on its own service the debt required to build the network. Under a user-funded-only structure (Case A), minimum DSCR is negative and averages 0.13x across the concession that is far below the 1.0x break-even threshold lenders require, let alone the 1.35x typically needed for investment-grade project debt.
A16: The Case for an Availability Payment
A17: Introducing a government availability payment (Case B), sized to deliver both a 1.35x minimum DSCR and a 12-15% equity IRR, restores the project to bankable metrics: 1.56x minimum DSCR, 13.5% equity IRR. The steady-state availability payment required is approximately CAD 18.4M/year consistent with the range the client's own Business Case had anticipated (CAD 15-25M/year).
A21: Sensitivity testing confirms this conclusion holds under downside scenarios (weaker traffic/occupancy,higher capex, higher interest rates):
A22: Case A remains unbankable in every scenario tested, while
A23: Case B remains resilient because the availability payment mechanism flexes with underlying performance.
A25: Status of This Model
A26: This is a working financial model built using Business Case figures, the original project brief, and standard Canadian project-finance and CCA/tax conventions. Every assumption is clearly flagged (see Assumptions tab and Read Me tab) and colour-coded (blue = input, red = flagged/solved). Two items in particular should be confirmed or refined before this goes to government:
... A39: Case B minimum DSCR 1.50x, equity IRR 13.5%, steady-state availability payment ~CAD 20.3M/year, present value of availability payments to the public authority ~CAD 212.2M over 30 years. See Read Me for full detail on every addition and the one remaining structuring concern (LLCR dips to 0.78x near debt maturity).

Sheet Dashboard
A1: FLEETPODS ALBERTA PHASE 1 : RESULTS DASHBOARD
A3: $155.1M program - 8 sites - 30-year concession - Case A vs Case B (PPP + Availability Payment)
B5: TOTAL PROGRAM CAPEX | D5: DEBT / EQUITY SPLIT | F5: MIN DSCR - CASE A (no AP) | H5: MIN DSCR - CASE B (with AP)
B6: =Summary!B4 -> 155 | D6: =Summary!B5&" / "&Summary!B6 -> 108.5 / 46.5 | F6: =Summary!B10 -> -1.0731362 | H6: =Summary!C10 -> 1.5046072
B8: EQUITY IRR - CASE A | D8: EQUITY IRR - CASE B | F8: STEADY-STATE AVAIL. PAYMENT | H8: DISCOUNTED PAYBACK - CASE B
B9: =Summary!B12 -> -0.12159604 | D9: =Summary!C12 -> 0.13503208 | F9: =Summary!B16 -> 20.277156 | H9: =Summary!C32 -> 30
B11: WHY AN AVAILABILITY PAYMENT IS REQUIRED
B12: Under Case A (user-fees only), the project cannot service its own debt: DSCR is negative in most operating years and averages well below the 1.0x break-even line across the 30-year concession.
B14: Under Case B, an availability payment sized to deliver both a 1.35x minimum DSCR AND a 12-15% equity IRR restores the project to bankable, investment-grade metrics without relying on user fees.
B17: DSCR PROFILE, CASE A vs CASE B (Years 5-30)

Sheet Assumptions
A1: ASSUMPTIONS
A3: 1. GENERAL & TIMING
A5: Study year | B5: 2026
A6: Concession start year | B6: 2027
A7: Concession life (years) | B7: 30
A8: Construction period (years) | B8: 4
A9: Gateway sites operational from Year | B9: 3
A10: Regional & Corridor-support sites operational from Year | B10: 4
A12: 2. SITE COUNTS & TYPOLOGY (Business Case Reference Case, $155M)
A14: Typology | B14: Count | C14: Capex/site $M | D14: Opex/site $M/yr
A15: Mega Hub (Calgary-Airdrie) | B15: 1 | C15: 53 | D15: 12
A16: Regional Hub (avg of 3) | B16: 3 | C16: 16.7 | D16: 3.73
A17: Infill Gateway Hub (avg of 4) | B17: 4 | C17: 7.85 | D17: 1.84
A18: Platform/Network Opex (steady-state) | B18: 2.6 | C18: $M/yr
A20: 3. CAPEX PHASING (% of site capex spent each construction year)
A22: Year of construction -> | B22: Year 1 | C22: Year 2 | D22: Year 3 | E22: Year 4
A23: Mega Hub phasing | B23: 0.2 | C23: 0.4 | D23: 0.4 | E23: 0
A24: Regional / Infill phasing | B24: 0.1 | C24: 0.3 | D24: 0.4 | E24: 0.2
A26: 4. PARKING REVENUE (steady-state; network total = 1,380 spaces per Business Case)
A28: Typology | B28: Stalls/site | C28: Occupancy % | D28: Rate $/stall-hr
A29: Mega Hub | B29: 460 | C29: 0.6 | D29: 8.5
A30: Regional (avg) | B30: 180 | C30: 0.5 | D30: 8.5
A31: Infill (avg) | B31: 80 | C31: 0.4 | D31: 8.5
A33: 5. RECOVERY POD REVENUE
A35: Typology | B35: Pods/site | C35: Occ. Yr5 of ops | D35: Occ. Yr10+ of ops | E35: Rate $/session
A36: Mega Hub | B36: 50 | C36: 0.45 | D36: 0.7 | E36: 125
A37: Regional (avg) | B37: 35 | C37: 0.4 | D37: 0.65 | E37: 125
A38: Infill (avg) | B38: 20 | C38: 0.35 | D38: 0.6 | E38: 125
A40: 6. FLEET SUBSCRIPTIONS & DIGITAL PLATFORM (network-level)
A42: Fleet count - Year 3 of concession | B42: 50
A43: Fleet count - Year 10+ of concession | B43: 140
A44: Average fee ($/fleet/month) | B44: 3250
A45: Digital platform revenue - Year 3 ($M) | B45: 0.6
A46: Digital platform revenue - Year 10+ ($M) | B46: 1.85
A48: 7. OTHER / ANCILLARY REVENUE (fuel, EV, food - simplified single line, $M/site/yr steady-state)
A50: Gateway | B50: 1.5
A51: Regional | B51: 0.5
A52: Corridor-support | B52: 0.2
A54: 8. RAMP-UP PROFILE (parking & ancillary revenue - % of steady-state, by years since site opened)
A56: Years since opening -> | B56: Yr 1 | C56: Yr 2 | D56: Yr 3 | E56: Yr 4 | F56: Yr 5+
...

Sheet Site Detail
A1: SITE-BY-SITE DETAIL (8 sites individually, per Business Case Reference Case)
A2: Stall/pod counts scaled from typology averages by each site's capex share (blue = input, editable per site).
A4: Site | B4: Capex $M | C4: Open Yr | D4: Stalls | E4: Park Occ% | F4: Park Rate | G4: Pods | H4: Pod Occ5 | I4: Pod Occ10 | J4: Pod Rate | K4: Opex $M/yr | L4: Other $M/yr
A5: Calgary-Airdrie (Mega) | B5: 53 | C5: 3 | D5: 460 | E5: 0.6 | F5: 8.5 | G5: 50 | H5: 0.45 | I5: 0.7 | J5: 125 | K5: 12 | L5: 1.5
A6: West Edmonton-Acheson | B6: 18 | C6: 4 | D6: 194 | E6: 0.5 | F6: 8.5 | G6: 38 | H6: 0.4 | I6: 0.65 | J6: 125 | K6: 4.028 | L6: 0.54
A7: Red Deer | B7: 16 | C7: 4 | D7: 173 | E7: 0.5 | F7: 8.5 | G7: 34 | H7: 0.4 | I7: 0.65 | J7: 125 | K7: 3.581 | L7: 0.48
A8: Fort McMurray-Suncor | B8: 16 | C8: 4 | D8: 173 | E8: 0.5 | F8: 8.5 | G8: 34 | H8: 0.4 | I8: 0.65 | J8: 125 | K8: 3.581 | L8: 0.48
A9: Seebe-Cochrane | B9: 8.2 | C9: 4 | D9: 84 | E9: 0.4 | F9: 8.5 | G9: 21 | H9: 0.35 | I9: 0.6 | J9: 125 | K9: 1.922 | L9: 0.209
A10: Brooks | B10: 7.7 | C10: 4 | D10: 79 | E10: 0.4 | F10: 8.5 | G10: 20 | H10: 0.35 | I10: 0.6 | J10: 125 | K10: 1.805 | L10: 0.196
A11: Medicine Hat | B11: 7.7 | C11: 4 | D11: 79 | E11: 0.4 | F11: 8.5 | G11: 20 | H11: 0.35 | I11: 0.6 | J11: 125 | K11: 1.805 | L11: 0.196
A12: Whitecourt-Fox Creek | B12: 7.8 | C12: 4 | D12: 80 | E12: 0.4 | F12: 8.5 | G12: 20 | H12: 0.35 | I12: 0.6 | J12: 125 | K12: 1.828 | L12: 0.199
A14: PER-SITE 30-YEAR SCHEDULES ($M)
A16: Calgary-Airdrie (Mega) - Years since opening | D16: =IF(Model!D3>=$C$5,Model!D3-$C$5+1,0) -> 0 | E16: =IF(Model!E3>=$C$5,Model!E3-$C$5+1,0) -> 0 | F16: =IF(Model!F3>=$C$5,Model!F3-$C$5+1,0) -> 1 | G16: =IF(Model!G3>=$C$5,Model!G3-$C$5+1,0) -> 2 | H16: =IF(Model!H3>=$C$5,Model!H3-$C$5+1,0) -> 3 | I16: =IF(Model!I3>=$C$5,Model!I3-$C$5+1,0) -> 4 | J16: =IF(Model!J3>=$C$5,Model!J3-$C$5+1,0) -> 5 | K16: =IF(Model!K3>=$C$5,Model!K3-$C$5+1,0) -> 6 | ... AG16: =IF(Model!AG3>=$C$5,Model!AG3-$C$5+1,0) -> 28
A17: Calgary-Airdrie (Mega) - Capex | D17: =IF(Model!D3<=4,$B$5*INDEX(Assumptions!$B$23:$E$23,Model!D3),0)*(1+Assumptions!$B$76) -> 10.6 | E17: =IF(Model!E3<=4,$B$5*INDEX(Assumptions!$B$23:$E$23,Model!E3),0)*(1+Assumptions!$B$76) -> 21.2 | F17: =IF(Model!F3<=4,$B$5*INDEX(Assumptions!$B$23:$E$23,Model!F3),0)*(1+Assumptions!$B$76) -> 21.2 | G17: =IF(Model!G3<=4,$B$5*INDEX(Assumptions!$B$23:$E$23,Model!G3),0)*(1+Assumptions!$B$76) -> 0 | H17: =IF(Model!H3<=4,$B$5*INDEX(Assumptions!$B$23:$E$23,Model!H3),0)*(1+Assumptions!$B$76) -> 0 | I17: =IF(Model!I3<=4,$B$5*INDEX(Assumptions!$B$23:$E$23,Model!I3),0)*(1+Assumptions!$B$76) -> 0 | J17: =IF(Model!J3<=4,$B$5*INDEX(Assumptions!$B$23:$E$23,Model!J3),0)*(1+Assumptions!$B$76) -> 0 | K17: =IF(Model!K3<=4,$B$5*INDEX(Assumptions!$B$23:$E$23,Model!K3),0)*(1+Assumptions!$B$76) -> 0 | ... AG17: =IF(Model!AG3<=4,$B$5*INDEX(Assumptions!$B$23:$E$23,Model!AG3),0)*(1+Assumptions!$B$76) -> 0
A18: Calgary-Airdrie (Mega) - Parking Revenue | D18: =$D$5*$E$5*(1+Assumptions!$B$75)*IF(D16<=0,0,INDEX(Assumptions!$B$57:$F$57,MIN(D16,5)))*8760*$F$5*(1+Assumptions!$B$71)^(Model!D3-1)*Assumptions!$B$80/1000000 -> 0 | E18: =$D$5*$E$5*(1+Assumptions!$B$75)*IF(E16<=0,0,INDEX(Assumptions!$B$57:$F$57,MIN(E16,5)))*8760*$F$5*(1+Assumptions!$B$71)^(Model!E3-1)*Assumptions!$B$80/1000000 -> 0 | F18: =$D$5*$E$5*(1+Assumptions!$B$75)*IF(F16<=0,0,INDEX(Assumptions!$B$57:$F$57,MIN(F16,5)))*8760*$F$5*(1+Assumptions!$B$71)^(Model!F3-1)*Assumptions!$B$80/1000000 -> 5.4410208 | G18: =$D$5*$E$5*(1+Assumptions!$B$75)*IF(G16<=0,0,INDEX(Assumptions!$B$57:$F$57,MIN(G16,5)))*8760*$F$5*(1+Assumptions!$B$71)^(Model!G3-1)*Assumptions!$B$80/1000000 -> 6.506554 | H18: =$D$5*$E$5*(1+Assumptions!$B$75)*IF(H16<=0,0,INDEX(Assumptions!$B$57:$F$57,MIN(H16,5)))*8760*$F$5*(1+Assumptions!$B$71)^(Model!H3-1)*Assumptions!$B$80/1000000 -> 8.098336 | I18: =$D$5*$E$5*(1+Assumptions!$B$75)*IF(I16<=0,0,INDEX(Assumptions!$B$57:$F$57,MIN(I16,5)))*8760*$F$5*(1+Assumptions!$B$71)^(Model!I3-1)*Assumptions!$B$80/1000000 -> 9.2773584 | J18: =$D$5*$E$5*(1+Assumptions!$B$75)*IF(J16<=0,0,INDEX(Assumptions!$B$57:$F$57,MIN(J16,5)))*8760*$F$5*(1+Assumptions!$B$71)^(Model!J3-1)*Assumptions!$B$80/1000000 -> 10.009781 | K18: =$D$5*$E$5*(1+Assumptions!$B$75)*IF(K16<=0,0,INDEX(Assumptions!$B$57:$F$57,MIN(K16,5)))*8760*$F$5*(1+Assumptions!$B$71)^(Model!K3-1)*Assumptions!$B$80/1000000 -> 10.260026 | ... AG18: =$D$5*$E$5*(1+Assumptions!$B$75)*IF(AG16<=0,0,INDEX(Assumptions!$B$57:$F$57,MIN(AG16,5)))*8760*$F$5*(1+Assumptions!$B$71)^(Model!AG3-1)*Assumptions!$B$80/1000000 -> 17.663367
A19: Calgary-Airdrie (Mega) - Pod Revenue | D19: =$G$5*(IF(D16<=0,0,IF(D16<=5,$H$5/5*D16,IF(D16<=10,$H$5+($I$5-$H$5)*(D16-5)/5,$I$5))))*365*(1+Assumptions!$B$75)*$J$5*(1+Assumptions!$B$71)^(Model!D3-1)*Assumptions!$B$80/1000000 -> 0 | E19: =$G$5*(IF(E16<=0,0,IF(E16<=5,$H$5/5*E16,IF(E16<=10,$H$5+($I$5-$H$5)*(E16-5)/5,$I$5))))*365*(1+Assumptions!$B$75)*$J$5*(1+Assumptions!$B$71)^(Model!E3-1)*Assumptions!$B$80/1000000 -> 0 | F19: =$G$5*(IF(F16<=0,0,IF(F16<=5,$H$5/5*F16,IF(F16<=10,$H$5+($I$5-$H$5)*(F16-5)/5,$I$5))))*365*(1+Assumptions!$B$75)*$J$5*(1+Assumptions!$B$71)^(Model!F3-1)*Assumptions!$B$80/1000000 -> 0.090596707 | G19: =$G$5*(IF(G16<=0,0,IF(G16<=5,$H$5/5*G16,IF(G16<=10,$H$5+($I$5-$H$5)*(G16-5)/5,$I$5))))*365*(1+Assumptions!$B$75)*$J$5*(1+Assumptions!$B$71)^(Model!G3-1)*Assumptions!$B$80/1000000 -> 0.18572325 | H19: =$G$5*(IF(H16<=0,0,IF(H16<=5,$H$5/5*H16,IF(H16<=10,$H$5+($I$5-$H$5)*(H16-5)/5,$I$5))))*365*(1+Assumptions!$B$75)*$J$5*(1+Assumptions!$B$71)^(Model!H3-1)*Assumptions!$B$80/1000000 -> 0.2855495 | I19: =$G$5*(IF(I16<=0,0,IF(I16<=5,$H$5/5*I16,IF(I16<=10,$H$5+($I$5-$H$5)*(I16-5)/5,$I$5))))*365*(1+Assumptions!$B$75)*$J$5*(1+Assumptions!$B$71)^(Model!I3-1)*Assumptions!$B$80/1000000 -> 0.39025098 | J19: =$G$5*(IF(J16<=0,0,IF(J16<=5,$H$5/5*J16,IF(J16<=10,$H$5+($I$5-$H$5)*(J16-5)/5,$I$5))))*365*(1+Assumptions!$B$75)*$J$5*(1+Assumptions!$B$71)^(Model!J3-1)*Assumptions!$B$80/1000000 -> 0.50000907 | K19: =$G$5*(IF(K16<=0,0,IF(K16<=5,$H$5/5*K16,IF(K16<=10,$H$5+($I$5-$H$5)*(K16-5)/5,$I$5))))*365*(1+Assumptions!$B$75)*$J$5*(1+Assumptions!$B$71)^(Model!K3-1)*Assumptions!$B$80/1000000 -> 0.56945477 | ... AG19: =$G$5*(IF(AG16<=0,0,IF(AG16<=5,$H$5/5*AG16,IF(AG16<=10,$H$5+($I$5-$H$5)*(AG16-5)/5,$I$5))))*365*(1+Assumptions!$B$75)*$J$5*(1+Assumptions!$B$71)^(Model!AG3-1)*Assumptions!$B$80/1000000 -> 1.3724999
A20: Calgary-Airdrie (Mega) - Other/Ancillary Revenue | D20: =$L$5*IF(D16<=0,0,INDEX(Assumptions!$B$57:$F$57,MIN(D16,5)))*(1+Assumptions!$B$71)^(Model!D3-1) -> 0 | E20: =$L$5*IF(E16<=0,0,INDEX(Assumptions!$B$57:$F$57,MIN(E16,5)))*(1+Assumptions!$B$71)^(Model!E3-1) -> 0 | F20: =$L$5*IF(F16<=0,0,INDEX(Assumptions!$B$57:$F$57,MIN(F16,5)))*(1+Assumptions!$B$71)^(Model!F3-1) -> 0.9455625 | G20: =$L$5*IF(G16<=0,0,INDEX(Assumptions!$B$57:$F$57,MIN(G16,5)))*(1+Assumptions!$B$71)^(Model!G3-1) -> 1.1307352 | H20: =$L$5*IF(H16<=0,0,INDEX(Assumptions!$B$57:$F$57,MIN(H16,5)))*(1+Assumptions!$B$71)^(Model!H3-1) -> 1.4073614 | I20: =$L$5*IF(I16<=0,0,INDEX(Assumptions!$B$57:$F$57,MIN(I16,5)))*(1+Assumptions!$B$71)^(Model!I3-1) -> 1.6122567 | J20: =$L$5*IF(J16<=0,0,INDEX(Assumptions!$B$57:$F$57,MIN(J16,5)))*(1+Assumptions!$B$71)^(Model!J3-1) -> 1.7395401 | K20: =$L$5*IF(K16<=0,0,INDEX(Assumptions!$B$57:$F$57,MIN(K16,5)))*(1+Assumptions!$B$71)^(Model!K3-1) -> 1.7830286 | ... AG20: =$L$5*IF(AG16<=0,0,INDEX(Assumptions!$B$57:$F$57,MIN(AG16,5)))*(1+Assumptions!$B$71)^(Model!AG3-1) -> 3.0696111
A21: Calgary-Airdrie (Mega) - Opex | D21: =IF(D16>0,$K$5*(1+Assumptions!$B$71)^(Model!D3-1),0) -> 0 | E21: =IF(E16>0,$K$5*(1+Assumptions!$B$71)^(Model!E3-1),0) -> 0 | F21: =IF(F16>0,$K$5*(1+Assumptions!$B$71)^(Model!F3-1),0) -> 12.6075 | G21: =IF(G16>0,$K$5*(1+Assumptions!$B$71)^(Model!G3-1),0) -> 12.922687 | H21: =IF(H16>0,$K$5*(1+Assumptions!$B$71)^(Model!H3-1),0) -> 13.245755 | I21: =IF(I16>0,$K$5*(1+Assumptions!$B$71)^(Model!I3-1),0) -> 13.576899 | J21: =IF(J16>0,$K$5*(1+Assumptions!$B$71)^(Model!J3-1),0) -> 13.916321 | K21: =IF(K16>0,$K$5*(1+Assumptions!$B$71)^(Model!K3-1),0) -> 14.264229 | ... AG21: =IF(AG16>0,$K$5*(1+Assumptions!$B$71)^(Model!AG3-1),0) -> 24.556889
A23: West Edmonton-Acheson - Years since opening | D23: =IF(Model!D3>=$C$6,Model!D3-$C$6+1,0) -> 0 | E23: =IF(Model!E3>=$C$6,Model!E3-$C$6+1,0) -> 0 | F23: =IF(Model!F3>=$C$6,Model!F3-$C$6+1,0) -> 0 | G23: =IF(Model!G3>=$C$6,Model!G3-$C$6+1,0) -> 1 | H23: =IF(Model!H3>=$C$6,Model!H3-$C$6+1,0) -> 2 | I23: =IF(Model!I3>=$C$6,Model!I3-$C$6+1,0) -> 3 | J23: =IF(Model!J3>=$C$6,Model!J3-$C$6+1,0) -> 4 | K23: =IF(Model!K3>=$C$6,Model!K3-$C$6+1,0) -> 5 | ... AG23: =IF(Model!AG3>=$C$6,Model!AG3-$C$6+1,0) -> 27
A24: West Edmonton-Acheson - Capex | D24: =IF(Model!D3<=4,$B$6*INDEX(Assumptions!$B$24:$E$24,Model!D3),0)*(1+Assumptions!$B$76) -> 1.8 | E24: =IF(Model!E3<=4,$B$6*INDEX(Assumptions!$B$24:$E$24,Model!E3),0)*(1+Assumptions!$B$76) -> 5.4 | F24: =IF(Model!F3<=4,$B$6*INDEX(Assumptions!$B$24:$E$24,Model!F3),0)*(1+Assumptions!$B$76) -> 7.2 | G24: =IF(Model!G3<=4,$B$6*INDEX(Assumptions!$B$24:$E$24,Model!G3),0)*(1+Assumptions!$B$76) -> 3.6 | H24: =IF(Model!H3<=4,$B$6*INDEX(Assumptions!$B$24:$E$24,Model!H3),0)*(1+Assumptions!$B$76) -> 0 | I24: =IF(Model!I3<=4,$B$6*INDEX(Assumptions!$B$24:$E$24,Model!I3),0)*(1+Assumptions!$B$76) -> 0 | J24: =IF(Model!J3<=4,$B$6*INDEX(Assumptions!$B$24:$E$24,Model!J3),0)*(1+Assumptions!$B$76) -> 0 | K24: =IF(Model!K3<=4,$B$6*INDEX(Assumptions!$B$24:$E$24,Model!K3),0)*(1+Assumptions!$B$76) -> 0 | ... AG24: =IF(Model!AG3<=4,$B$6*INDEX(Assumptions!$B$24:$E$24,Model!AG3),0)*(1+Assumptions!$B$76) -> 0
A25: West Edmonton-Acheson - Parking Revenue | D25: =$D$6*$E$6*(1+Assumptions!$B$75)*IF(D23<=0,0,INDEX(Assumptions!$B$57:$F$57,MIN(D23,5)))*8760*$F$6*(1+Assumptions!$B$71)^(Model!D3-1)*Assumptions!$B$80/1000000 -> 0 | E25: =$D$6*$E$6*(1+Assumptions!$B$75)*IF(E23<=0,0,INDEX(Assumptions!$B$57:$F$57,MIN(E23,5)))*8760*$F$6*(1+Assumptions!$B$71)^(Model!E3-1)*Assumptions!$B$80/1000000 -> 0 | F25: =$D$6*$E$6*(1+Assumptions!$B$75)*IF(F23<=0,0,INDEX(Assumptions!$B$57:$F$57,MIN(F23,5)))*8760*$F$6*(1+Assumptions!$B$71)^(Model!F3-1)*Assumptions!$B$80/1000000 -> 0 | G25: =$D$6*$E$6*(1+Assumptions!$B$75)*IF(G23<=0,0,INDEX(Assumptions!$B$57:$F$57,MIN(G23,5)))*8760*$F$6*(1+Assumptions!$B$71)^(Model!G3-1)*Assumptions!$B$80/1000000 -> 1.9600489 | H25: =$D$6*$E$6*(1+Assumptions!$B$75)*IF(H23<=0,0,INDEX(Assumptions!$B$57:$F$57,MIN(H23,5)))*8760*$F$6*(1+Assumptions!$B$71)^(Model!H3-1)*Assumptions!$B$80/1000000 -> 2.3438918 | I25: =$D$6*$E$6*(1+Assumptions!$B$75)*IF(I23<=0,0,INDEX(Assumptions!$B$57:$F$57,MIN(I23,5)))*8760*$F$6*(1+Assumptions!$B$71)^(Model!I3-1)*Assumptions!$B$80/1000000 -> 2.9173082 | J25: =$D$6*$E$6*(1+Assumptions!$B$75)*IF(J23<=0,0,INDEX(Assumptions!$B$57:$F$57,MIN(J23,5)))*8760*$F$6*(1+Assumptions!$B$71)^(Model!J3-1)*Assumptions!$B$80/1000000 -> 3.3420339 | K25: =$D$6*$E$6*(1+Assumptions!$B$75)*IF(K23<=0,0,INDEX(Assumptions!$B$57:$F$57,MIN(K23,5)))*8760*$F$6*(1+Assumptions!$B$71)^(Model!K3-1)*Assumptions!$B$80/1000000 -> 3.6058787 | ... AG25: =$D$6*$E$6*(1+Assumptions!$B$75)*IF(AG23<=0,0,INDEX(Assumptions!$B$57:$F$57,MIN(AG23,5)))*8760*$F$6*(1+Assumptions!$B$71)^(Model!AG3-1)*Assumptions!$B$80/1000000 -> 6.2077776
A26: West Edmonton-Acheson - Pod Revenue | D26: =$G$6*(IF(D23<=0,0,IF(D23<=5,$H$6/5*D23,IF(D23<=10,$H$6+($I$6-$H$6)*(D23-5)/5,$I$6))))*365*(1+Assumptions!$B$75)*$J$6*(1+Assumptions!$B$71)^(Model!D3-1)*Assumptions!$B$80/1000000 -> 0 | E26: =$G$6*(IF(E23<=0,0,IF(E23<=5,$H$6/5*E23,IF(E23<=10,$H$6+($I$6-$H$6)*(E23-5)/5,$I$6))))*365*(1+Assumptions!$B$75)*$J$6*(1+Assumptions!$B$71)^(Model!E3-1)*Assumptions!$B$80/1000000 -> 0 | F26: =$G$6*(IF(F23<=0,0,IF(F23<=5,$H$6/5*F23,IF(F23<=10,$H$6+($I$6-$H$6)*(F23-5)/5,$I$6))))*365*(1+Assumptions!$B$75)*$J$6*(1+Assumptions!$B$71)^(Model!F3-1)*Assumptions!$B$80/1000000 -> 0 | G26: =$G$6*(IF(G23<=0,0,IF(G23<=5,$H$6/5*G23,IF(G23<=10,$H$6+($I$6-$H$6)*(G23-5)/5,$I$6))))*365*(1+Assumptions!$B$75)*$J$6*(1+Assumptions!$B$71)^(Model!G3-1)*Assumptions!$B$80/1000000 -> 0.062733186 | H26: =$G$6*(IF(H23<=0,0,IF(H23<=5,$H$6/5*H23,IF(H23<=10,$H$6+($I$6-$H$6)*(H23-5)/5,$I$6))))*365*(1+Assumptions!$B$75)*$J$6*(1+Assumptions!$B$71)^(Model!H3-1)*Assumptions!$B$80/1000000 -> 0.12860303 | I26: =$G$6*(IF(I23<=0,0,IF(I23<=5,$H$6/5*I23,IF(I23<=10,$H$6+($I$6-$H$6)*(I23-5)/5,$I$6))))*365*(1+Assumptions!$B$75)*$J$6*(1+Assumptions!$B$71)^(Model!I3-1)*Assumptions!$B$80/1000000 -> 0.19772716 | J26: =$G$6*(IF(J23<=0,0,IF(J23<=5,$H$6/5*J23,IF(J23<=10,$H$6+($I$6-$H$6)*(J23-5)/5,$I$6))))*365*(1+Assumptions!$B$75)*$J$6*(1+Assumptions!$B$71)^(Model!J3-1)*Assumptions!$B$80/1000000 -> 0.27022712 | K26: =$G$6*(IF(K23<=0,0,IF(K23<=5,$H$6/5*K23,IF(K23<=10,$H$6+($I$6-$H$6)*(K23-5)/5,$I$6))))*365*(1+Assumptions!$B$75)*$J$6*(1+Assumptions!$B$71)^(Model!K3-1)*Assumptions!$B$80/1000000 -> 0.3462285 | ... AG26: =$G$6*(IF(AG23<=0,0,IF(AG23<=5,$H$6/5*AG23,IF(AG23<=10,$H$6+($I$6-$H$6)*(AG23-5)/5,$I$6))))*365*(1+Assumptions!$B$75)*$J$6*(1+Assumptions!$B$71)^(Model!AG3-1)*Assumptions!$B$80/1000000 -> 0.96859276
A27: West Edmonton-Acheson - Other/Ancillary Revenue | D27: =$L$6*IF(D23<=0,0,INDEX(Assumptions!$B$57:$F$57,MIN(D23,5)))*(1+Assumptions!$B$71)^(Model!D3-1) -> 0 | E27: =$L$6*IF(E23<=0,0,INDEX(Assumptions!$B$57:$F$57,MIN(E23,5)))*(1+Assumptions!$B$71)^(Model!E3-1) -> 0 | F27: =$L$6*IF(F23<=0,0,INDEX(Assumptions!$B$57:$F$57,MIN(F23,5)))*(1+Assumptions!$B$71)^(Model!F3-1) -> 0 | G27: =$L$6*IF(G23<=0,0,INDEX(Assumptions!$B$57:$F$57,MIN(G23,5)))*(1+Assumptions!$B$71)^(Model!G3-1) -> 0.34891256 | H27: =$L$6*IF(H23<=0,0,INDEX(Assumptions!$B$57:$F$57,MIN(H23,5)))*(1+Assumptions!$B$71)^(Model!H3-1) -> 0.41724127 | I27: =$L$6*IF(I23<=0,0,INDEX(Assumptions!$B$57:$F$57,MIN(I23,5)))*(1+Assumptions!$B$71)^(Model!I3-1) -> 0.51931637 | J27: =$L$6*IF(J23<=0,0,INDEX(Assumptions!$B$57:$F$57,MIN(J23,5)))*(1+Assumptions!$B$71)^(Model!J3-1) -> 0.59492272 | K27: =$L$6*IF(K23<=0,0,INDEX(Assumptions!$B$57:$F$57,MIN(K23,5)))*(1+Assumptions!$B$71)^(Model!K3-1) -> 0.64189031 | ... AG27: =$L$6*IF(AG23<=0,0,INDEX(Assumptions!$B$57:$F$57,MIN(AG23,5)))*(1+Assumptions!$B$71)^(Model!AG3-1) -> 1.10506
A28: West Edmonton-Acheson - Opex | D28: =IF(D23>0,$K$6*(1+Assumptions!$B$71)^(Model!D3-1),0) -> 0 | E28: =IF(E23>0,$K$6*(1+Assumptions!$B$71)^(Model!E3-1),0) -> 0 | F28: =IF(F23>0,$K$6*(1+Assumptions!$B$71)^(Model!F3-1),0) -> 0 | G28: =IF(G23>0,$K$6*(1+Assumptions!$B$71)^(Model!G3-1),0) -> 4.3377154 | H28: =IF(H23>0,$K$6*(1+Assumptions!$B$71)^(Model!H3-1),0) -> 4.4461583 | I28: =IF(I23>0,$K$6*(1+Assumptions!$B$71)^(Model!I3-1),0) -> 4.5573123 | J28: =IF(J23>0,$K$6*(1+Assumptions!$B$71)^(Model!J3-1),0) -> 4.6712451 | K28: =IF(K23>0,$K$6*(1+Assumptions!$B$71)^(Model!K3-1),0) -> 4.7880262 | ... AG28: =IF(AG23>0,$K$6*(1+Assumptions!$B$71)^(Model!AG3-1),0) -> 8.242929
A30: Red Deer - Years since opening | D30: =IF(Model!D3>=$C$7,Model!D3-$C$7+1,0) -> 0 | E30: =IF(Model!E3>=$C$7,Model!E3-$C$7+1,0) -> 0 | F30: =IF(Model!F3>=$C$7,Model!F3-$C$7+1,0) -> 0 | G30: =IF(Model!G3>=$C$7,Model!G3-$C$7+1,0) -> 1 | H30: =IF(Model!H3>=$C$7,Model!H3-$C$7+1,0) -> 2 | I30: =IF(Model!I3>=$C$7,Model!I3-$C$7+1,0) -> 3 | J30: =IF(Model!J3>=$C$7,Model!J3-$C$7+1,0) -> 4 | K30: =IF(Model!K3>=$C$7,Model!K3-$C$7+1,0) -> 5 | ... AG30: =IF(Model!AG3>=$C$7,Model!AG3-$C$7+1,0) -> 27
A31: Red Deer - Capex | D31: =IF(Model!D3<=4,$B$7*INDEX(Assumptions!$B$24:$E$24,Model!D3),0)*(1+Assumptions!$B$76) -> 1.6 | E31: =IF(Model!E3<=4,$B$7*INDEX(Assumptions!$B$24:$E$24,Model!E3),0)*(1+Assumptions!$B$76) -> 4.8 | F31: =IF(Model!F3<=4,$B$7*INDEX(Assumptions!$B$24:$E$24,Model!F3),0)*(1+Assumptions!$B$76) -> 6.4 | G31: =IF(Model!G3<=4,$B$7*INDEX(Assumptions!$B$24:$E$24,Model!G3),0)*(1+Assumptions!$B$76) -> 3.2 | H31: =IF(Model!H3<=4,$B$7*INDEX(Assumptions!$B$24:$E$24,Model!H3),0)*(1+Assumptions!$B$76) -> 0 | I31: =IF(Model!I3<=4,$B$7*INDEX(Assumptions!$B$24:$E$24,Model!I3),0)*(1+Assumptions!$B$76) -> 0 | J31: =IF(Model!J3<=4,$B$7*INDEX(Assumptions!$B$24:$E$24,Model!J3),0)*(1+Assumptions!$B$76) -> 0 | K31: =IF(Model!K3<=4,$B$7*INDEX(Assumptions!$B$24:$E$24,Model!K3),0)*(1+Assumptions!$B$76) -> 0 | ... AG31: =IF(Model!AG3<=4,$B$7*INDEX(Assumptions!$B$24:$E$24,Model!AG3),0)*(1+Assumptions!$B$76) -> 0
A32: Red Deer - Parking Revenue | D32: =$D$7*$E$7*(1+Assumptions!$B$75)*IF(D30<=0,0,INDEX(Assumptions!$B$57:$F$57,MIN(D30,5)))*8760*$F$7*(1+Assumptions!$B$71)^(Model!D3-1)*Assumptions!$B$80/1000000 -> 0 | E32: =$D$7*$E$7*(1+Assumptions!$B$75)*IF(E30<=0,0,INDEX(Assumptions!$B$57:$F$57,MIN(E30,5)))*8760*$F$7*(1+Assumptions!$B$71)^(Model!E3-1)*Assumptions!$B$80/1000000 -> 0 | F32: =$D$7*$E$7*(1+Assumptions!$B$75)*IF(F30<=0,0,INDEX(Assumptions!$B$57:$F$57,MIN(F30,5)))*8760*$F$7*(1+Assumptions!$B$71)^(Model!F3-1)*Assumptions!$B$80/1000000 -> 0 | G32: =$D$7*$E$7*(1+Assumptions!$B$75)*IF(G30<=0,0,INDEX(Assumptions!$B$57:$F$57,MIN(G30,5)))*8760*$F$7*(1+Assumptions!$B$71)^(Model!G3-1)*Assumptions!$B$80/1000000 -> 1.7478786 | H32: =$D$7*$E$7*(1+Assumptions!$B$75)*IF(H30<=0,0,INDEX(Assumptions!$B$57:$F$57,MIN(H30,5)))*8760*$F$7*(1+Assumptions!$B$71)^(Model!H3-1)*Assumptions!$B$80/1000000 -> 2.0901715 | I32: =$D$7*$E$7*(1+Assumptions!$B$75)*IF(I30<=0,0,INDEX(Assumptions!$B$57:$F$57,MIN(I30,5)))*8760*$F$7*(1+Assumptions!$B$71)^(Model!I3-1)*Assumptions!$B$80/1000000 -> 2.6015171 | J32: =$D$7*$E$7*(1+Assumptions!$B$75)*IF(J30<=0,0,INDEX(Assumptions!$B$57:$F$57,MIN(J30,5)))*8760*$F$7*(1+Assumptions!$B$71)^(Model!J3-1)*Assumptions!$B$80/1000000 -> 2.9802674 | K32: =$D$7*$E$7*(1+Assumptions!$B$75)*IF(K30<=0,0,INDEX(Assumptions!$B$57:$F$57,MIN(K30,5)))*8760*$F$7*(1+Assumptions!$B$71)^(Model!K3-1)*Assumptions!$B$80/1000000 -> 3.2155516 | ... AG32: =$D$7*$E$7*(1+Assumptions!$B$75)*IF(AG30<=0,0,INDEX(Assumptions!$B$57:$F$57,MIN(AG30,5)))*8760*$F$7*(1+Assumptions!$B$71)^(Model!AG3-1)*Assumptions!$B$80/1000000 -> 5.5358017
A33: Red Deer - Pod Revenue | D33: =$G$7*(IF(D30<=0,0,IF(D30<=5,$H$7/5*D30,IF(D30<=10,$H$7+($I$7-$H$7)*(D30-5)/5,$I$7))))*365*(1+Assumptions!$B$75)*$J$7*(1+Assumptions!$B$71)^(Model!D3-1)*Assumptions!$B$80/1000000 -> 0 | E33: =$G$7*(IF(E30<=0,0,IF(E30<=5,$H$7/5*E30,IF(E30<=10,$H$7+($I$7-$H$7)*(E30-5)/5,$I$7))))*365*(1+Assumptions!$B$75)*$J$7*(1+Assumptions!$B$71)^(Model!E3-1)*Assumptions!$B$80/1000000 -> 0 | F33: =$G$7*(IF(F30<=0,0,IF(F30<=5,$H$7/5*F30,IF(F30<=10,$H$7+($I$7-$H$7)*(F30-5)/5,$I$7))))*365*(1+Assumptions!$B$75)*$J$7*(1+Assumptions!$B$71)^(Model!F3-1)*Assumptions!$B$80/1000000 -> 0 | G33: =$G$7*(IF(G30<=0,0,IF(G30<=5,$H$7/5*G30,IF(G30<=10,$H$7+($I$7-$H$7)*(G30-5)/5,$I$7))))*365*(1+Assumptions!$B$75)*$J$7*(1+Assumptions!$B$71)^(Model!G3-1)*Assumptions!$B$80/1000000 -> 0.056129693 | H33: =$G$7*(IF(H30<=0,0,IF(H30<=5,$H$7/5*H30,IF(H30<=10,$H$7+($I$7-$H$7)*(H30-5)/5,$I$7))))*365*(1+Assumptions!$B$75)*$J$7*(1+Assumptions!$B$71)^(Model!H3-1)*Assumptions!$B$80/1000000 -> 0.11506587 | I33: =$G$7*(IF(I30<=0,0,IF(I30<=5,$H$7/5*I30,IF(I30<=10,$H$7+($I$7-$H$7)*(I30-5)/5,$I$7))))*365*(1+Assumptions!$B$75)*$J$7*(1+Assumptions!$B$71)^(Model!I3-1)*Assumptions!$B$80/1000000 -> 0.17691378 | J33: =$G$7*(IF(J30<=0,0,IF(J30<=5,$H$7/5*J30,IF(J30<=10,$H$7+($I$7-$H$7)*(J30-5)/5,$I$7))))*365*(1+Assumptions!$B$75)*$J$7*(1+Assumptions!$B$71)^(Model!J3-1)*Assumptions!$B$80/1000000 -> 0.24178216 | K33: =$G$7*(IF(K30<=0,0,IF(K30<=5,$H$7/5*K30,IF(K30<=10,$H$7+($I$7-$H$7)*(K30-5)/5,$I$7))))*365*(1+Assumptions!$B$75)*$J$7*(1+Assumptions!$B$71)^(Model!K3-1)*Assumptions!$B$80/1000000 -> 0.30978339 | ... AG33: =$G$7*(IF(AG30<=0,0,IF(AG30<=5,$H$7/5*AG30,IF(AG30<=10,$H$7+($I$7-$H$7)*(AG30-5)/5,$I$7))))*365*(1+Assumptions!$B$75)*$J$7*(1+Assumptions!$B$71)^(Model!AG3-1)*Assumptions!$B$80/1000000 -> 0.86663563
A34: Red Deer - Other/Ancillary Revenue | D34: =$L$7*IF(D30<=0,0,INDEX(Assumptions!$B$57:$F$57,MIN(D30,5)))*(1+Assumptions!$B$71)^(Model!D3-1) -> 0 | E34: =$L$7*IF(E30<=0,0,INDEX(Assumptions!$B$57:$F$57,MIN(E30,5)))*(1+Assumptions!$B$71)^(Model!E3-1) -> 0 | F34: =$L$7*IF(F30<=0,0,INDEX(Assumptions!$B$57:$F$57,MIN(F30,5)))*(1+Assumptions!$B$71)^(Model!F3-1) -> 0 | G34: =$L$7*IF(G30<=0,0,INDEX(Assumptions!$B$57:$F$57,MIN(G30,5)))*(1+Assumptions!$B$71)^(Model!G3-1) -> 0.3101445 | H34: =$L$7*IF(H30<=0,0,INDEX(Assumptions!$B$57:$F$57,MIN(H30,5)))*(1+Assumptions!$B$71)^(Model!H3-1) -> 0.37088113 | I34: =$L$7*IF(I30<=0,0,INDEX(Assumptions!$B$57:$F$57,MIN(I30,5)))*(1+Assumptions!$B$71)^(Model!I3-1) -> 0.46161455 | J34: =$L$7*IF(J30<=0,0,INDEX(Assumptions!$B$57:$F$57,MIN(J30,5)))*(1+Assumptions!$B$71)^(Model!J3-1) -> 0.5288202 | K34: =$L$7*IF(K30<=0,0,INDEX(Assumptions!$B$57:$F$57,MIN(K30,5)))*(1+Assumptions!$B$71)^(Model!K3-1) -> 0.57056916 | ... AG34: =$L$7*IF(AG30<=0,0,INDEX(Assumptions!$B$57:$F$57,MIN(AG30,5)))*(1+Assumptions!$B$71)^(Model!AG3-1) -> 0.98227555
A35: Red Deer - Opex | D35: =IF(D30>0,$K$7*(1+Assumptions!$B$71)^(Model!D3-1),0) -> 0 | E35: =IF(E30>0,$K$7*(1+Assumptions!$B$71)^(Model!E3-1),0) -> 0 | F35: =IF(F30>0,$K$7*(1+Assumptions!$B$71)^(Model!F3-1),0) -> 0 | G35: =IF(G30>0,$K$7*(1+Assumptions!$B$71)^(Model!G3-1),0) -> 3.8563453 | H35: =IF(H30>0,$K$7*(1+Assumptions!$B$71)^(Model!H3-1),0) -> 3.952754 | I35: =IF(I30>0,$K$7*(1+Assumptions!$B$71)^(Model!I3-1),0) -> 4.0515728 | J35: =IF(J30>0,$K$7*(1+Assumptions!$B$71)^(Model!J3-1),0) -> 4.1528621 | K35: =IF(K30>0,$K$7*(1+Assumptions!$B$71)^(Model!K3-1),0) -> 4.2566837 | ... AG35: =IF(AG30>0,$K$7*(1+Assumptions!$B$71)^(Model!AG3-1),0) -> 7.3281849
A37: Fort McMurray-Suncor - Years since opening | D37: =IF(Model!D3>=$C$8,Model!D3-$C$8+1,0) -> 0 | E37: =IF(Model!E3>=$C$8,Model!E3-$C$8+1,0) -> 0 | F37: =IF(Model!F3>=$C$8,Model!F3-$C$8+1,0) -> 0 | G37: =IF(Model!G3>=$C$8,Model!G3-$C$8+1,0) -> 1 | H37: =IF(Model!H3>=$C$8,Model!H3-$C$8+1,0) -> 2 | I37: =IF(Model!I3>=$C$8,Model!I3-$C$8+1,0) -> 3 | J37: =IF(Model!J3>=$C$8,Model!J3-$C$8+1,0) -> 4 | K37: =IF(Model!K3>=$C$8,Model!K3-$C$8+1,0) -> 5 | ... AG37: =IF(Model!AG3>=$C$8,Model!AG3-$C$8+1,0) -> 27
A38: Fort McMurray-Suncor - Capex | D38: =IF(Model!D3<=4,$B$8*INDEX(Assumptions!$B$24:$E$24,Model!D3),0)*(1+Assumptions!$B$76) -> 1.6 | E38: =IF(Model!E3<=4,$B$8*INDEX(Assumptions!$B$24:$E$24,Model!E3),0)*(1+Assumptions!$B$76) -> 4.8 | F38: =IF(Model!F3<=4,$B$8*INDEX(Assumptions!$B$24:$E$24,Model!F3),0)*(1+Assumptions!$B$76) -> 6.4 | G38: =IF(Model!G3<=4,$B$8*INDEX(Assumptions!$B$24:$E$24,Model!G3),0)*(1+Assumptions!$B$76) -> 3.2 | H38: =IF(Model!H3<=4,$B$8*INDEX(Assumptions!$B$24:$E$24,Model!H3),0)*(1+Assumptions!$B$76) -> 0 | I38: =IF(Model!I3<=4,$B$8*INDEX(Assumptions!$B$24:$E$24,Model!I3),0)*(1+Assumptions!$B$76) -> 0 | J38: =IF(Model!J3<=4,$B$8*INDEX(Assumptions!$B$24:$E$24,Model!J3),0)*(1+Assumptions!$B$76) -> 0 | K38: =IF(Model!K3<=4,$B$8*INDEX(Assumptions!$B$24:$E$24,Model!K3),0)*(1+Assumptions!$B$76) -> 0 | ... AG38: =IF(Model!AG3<=4,$B$8*INDEX(Assumptions!$B$24:$E$24,Model!AG3),0)*(1+Assumptions!$B$76) -> 0
A39: Fort McMurray-Suncor - Parking Revenue | D39: =$D$8*$E$8*(1+Assumptions!$B$75)*IF(D37<=0,0,INDEX(Assumptions!$B$57:$F$57,MIN(D37,5)))*8760*$F$8*(1+Assumptions!$B$71)^(Model!D3-1)*Assumptions!$B$80/1000000 -> 0 | E39: =$D$8*$E$8*(1+Assumptions!$B$75)*IF(E37<=0,0,INDEX(Assumptions!$B$57:$F$57,MIN(E37,5)))*8760*$F$8*(1+Assumptions!$B$71)^(Model!E3-1)*Assumptions!$B$80/1000000 -> 0 | F39: =$D$8*$E$8*(1+Assumptions!$B$75)*IF(F37<=0,0,INDEX(Assumptions!$B$57:$F$57,MIN(F37,5)))*8760*$F$8*(1+Assumptions!$B$71)^(Model!F3-1)*Assumptions!$B$80/1000000 -> 0 | G39: =$D$8*$E$8*(1+Assumptions!$B$75)*IF(G37<=0,0,INDEX(Assumptions!$B$57:$F$57,MIN(G37,5)))*8760*$F$8*(1+Assumptions!$B$71)^(Model!G3-1)*Assumptions!$B$80/1000000 -> 1.7478786 | H39: =$D$8*$E$8*(1+Assumptions!$B$75)*IF(H37<=0,0,INDEX(Assumptions!$B$57:$F$57,MIN(H37,5)))*8760*$F$8*(1+Assumptions!$B$71)^(Model!H3-1)*Assumptions!$B$80/1000000 -> 2.0901715 | I39: =$D$8*$E$8*(1+Assumptions!$B$75)*IF(I37<=0,0,INDEX(Assumptions!$B$57:$F$57,MIN(I37,5)))*8760*$F$8*(1+Assumptions!$B$71)^(Model!I3-1)*Assumptions!$B$80/1000000 -> 2.6015171 | J39: =$D$8*$E$8*(1+Assumptions!$B$75)*IF(J37<=0,0,INDEX(Assumptions!$B$57:$F$57,MIN(J37,5)))*8760*$F$8*(1+Assumptions!$B$71)^(Model!J3-1)*Assumptions!$B$80/1000000 -> 2.9802674 | K39: =$D$8*$E$8*(1+Assumptions!$B$75)*IF(K37<=0,0,INDEX(Assumptions!$B$57:$F$57,MIN(K37,5)))*8760*$F$8*(1+Assumptions!$B$71)^(Model!K3-1)*Assumptions!$B$80/1000000 -> 3.2155516 | ... AG39: =$D$8*$E$8*(1+Assumptions!$B$75)*IF(AG37<=0,0,INDEX(Assumptions!$B$57:$F$57,MIN(AG37,5)))*8760*$F$8*(1+Assumptions!$B$71)^(Model!AG3-1)*Assumptions!$B$80/1000000 -> 5.5358017
A40: Fort McMurray-Suncor - Pod Revenue | D40: =$G$8*(IF(D37<=0,0,IF(D37<=5,$H$8/5*D37,IF(D37<=10,$H$8+($I$8-$H$8)*(D37-5)/5,$I$8))))*365*(1+Assumptions!$B$75)*$J$8*(1+Assumptions!$B$71)^(Model!D3-1)*Assumptions!$B$80/1000000 -> 0 | E40: =$G$8*(IF(E37<=0,0,IF(E37<=5,$H$8/5*E37,IF(E37<=10,$H$8+($I$8-$H$8)*(E37-5)/5,$I$8))))*365*(1+Assumptions!$B$75)*$J$8*(1+Assumptions!$B$71)^(Model!E3-1)*Assumptions!$B$80/1000000 -> 0 | F40: =$G$8*(IF(F37<=0,0,IF(F37<=5,$H$8/5*F37,IF(F37<=10,$H$8+($I$8-$H$8)*(F37-5)/5,$I$8))))*365*(1+Assumptions!$B$75)*$J$8*(1+Assumptions!$B$71)^(Model!F3-1)*Assumptions!$B$80/1000000 -> 0 | G40: =$G$8*(IF(G37<=0,0,IF(G37<=5,$H$8/5*G37,IF(G37<=10,$H$8+($I$8-$H$8)*(G37-5)/5,$I$8))))*365*(1+Assumptions!$B$75)*$J$8*(1+Assumptions!$B$71)^(Model!G3-1)*Assumptions!$B$80/1000000 -> 0.056129693 | H40: =$G$8*(IF(H37<=0,0,IF(H37<=5,$H$8/5*H37,IF(H37<=10,$H$8+($I$8-$H$8)*(H37-5)/5,$I$8))))*365*(1+Assumptions!$B$75)*$J$8*(1+Assumptions!$B$71)^(Model!H3-1)*Assumptions!$B$80/1000000 -> 0.11506587 | I40: =$G$8*(IF(I37<=0,0,IF(I37<=5,$H$8/5*I37,IF(I37<=10,$H$8+($I$8-$H$8)*(I37-5)/5,$I$8))))*365*(1+Assumptions!$B$75)*$J$8*(1+Assumptions!$B$71)^(Model!I3-1)*Assumptions!$B$80/1000000 -> 0.17691378 | J40: =$G$8*(IF(J37<=0,0,IF(J37<=5,$H$8/5*J37,IF(J37<=10,$H$8+($I$8-$H$8)*(J37-5)/5,$I$8))))*365*(1+Assumptions!$B$75)*$J$8*(1+Assumptions!$B$71)^(Model!J3-1)*Assumptions!$B$80/1000000 -> 0.24178216 | K40: =$G$8*(IF(K37<=0,0,IF(K37<=5,$H$8/5*K37,IF(K37<=10,$H$8+($I$8-$H$8)*(K37-5)/5,$I$8))))*365*(1+Assumptions!$B$75)*$J$8*(1+Assumptions!$B$71)^(Model!K3-1)*Assumptions!$B$80/1000000 -> 0.30978339 | ... AG40: =$G$8*(IF(AG37<=0,0,IF(AG37<=5,$H$8/5*AG37,IF(AG37<=10,$H$8+($I$8-$H$8)*(AG37-5)/5,$I$8))))*365*(1+Assumptions!$B$75)*$J$8*(1+Assumptions!$B$71)^(Model!AG3-1)*Assumptions!$B$80/1000000 -> 0.86663563
A41: Fort McMurray-Suncor - Other/Ancillary Revenue | D41: =$L$8*IF(D37<=0,0,INDEX(Assumptions!$B$57:$F$57,MIN(D37,5)))*(1+Assumptions!$B$71)^(Model!D3-1) -> 0 | E41: =$L$8*IF(E37<=0,0,INDEX(Assumptions!$B$57:$F$57,MIN(E37,5)))*(1+Assumptions!$B$71)^(Model!E3-1) -> 0 | F41: =$L$8*IF(F37<=0,0,INDEX(Assumptions!$B$57:$F$57,MIN(F37,5)))*(1+Assumptions!$B$71)^(Model!F3-1) -> 0 | G41: =$L$8*IF(G37<=0,0,INDEX(Assumptions!$B$57:$F$57,MIN(G37,5)))*(1+Assumptions!$B$71)^(Model!G3-1) -> 0.3101445 | H41: =$L$8*IF(H37<=0,0,INDEX(Assumptions!$B$57:$F$57,MIN(H37,5)))*(1+Assumptions!$B$71)^(Model!H3-1) -> 0.37088113 | I41: =$L$8*IF(I37<=0,0,INDEX(Assumptions!$B$57:$F$57,MIN(I37,5)))*(1+Assumptions!$B$71)^(Model!I3-1) -> 0.46161455 | J41: =$L$8*IF(J37<=0,0,INDEX(Assumptions!$B$57:$F$57,MIN(J37,5)))*(1+Assumptions!$B$71)^(Model!J3-1) -> 0.5288202 | K41: =$L$8*IF(K37<=0,0,INDEX(Assumptions!$B$57:$F$57,MIN(K37,5)))*(1+Assumptions!$B$71)^(Model!K3-1) -> 0.57056916 | ... AG41: =$L$8*IF(AG37<=0,0,INDEX(Assumptions!$B$57:$F$57,MIN(AG37,5)))*(1+Assumptions!$B$71)^(Model!AG3-1) -> 0.98227555
A42: Fort McMurray-Suncor - Opex | D42: =IF(D37>0,$K$8*(1+Assumptions!$B$71)^(Model!D3-1),0) -> 0 | E42: =IF(E37>0,$K$8*(1+Assumptions!$B$71)^(Model!E3-1),0) -> 0 | F42: =IF(F37>0,$K$8*(1+Assumptions!$B$71)^(Model!F3-1),0) -> 0 | G42: =IF(G37>0,$K$8*(1+Assumptions!$B$71)^(Model!G3-1),0) -> 3.8563453 | H42: =IF(H37>0,$K$8*(1+Assumptions!$B$71)^(Model!H3-1),0) -> 3.952754 | I42: =IF(I37>0,$K$8*(1+Assumptions!$B$71)^(Model!I3-1),0) -> 4.0515728 | J42: =IF(J37>0,$K$8*(1+Assumptions!$B$71)^(Model!J3-1),0) -> 4.1528621 | K42: =IF(K37>0,$K$8*(1+Assumptions!$B$71)^(Model!K3-1),0) -> 4.2566837 | ... AG42: =IF(AG37>0,$K$8*(1+Assumptions!$B$71)^(Model!AG3-1),0) -> 7.3281849
A44: Seebe-Cochrane - Years since opening | D44: =IF(Model!D3>=$C$9,Model!D3-$C$9+1,0) -> 0 | E44: =IF(Model!E3>=$C$9,Model!E3-$C$9+1,0) -> 0 | F44: =IF(Model!F3>=$C$9,Model!F3-$C$9+1,0) -> 0 | G44: =IF(Model!G3>=$C$9,Model!G3-$C$9+1,0) -> 1 | H44: =IF(Model!H3>=$C$9,Model!H3-$C$9+1,0) -> 2 | I44: =IF(Model!I3>=$C$9,Model!I3-$C$9+1,0) -> 3 | J44: =IF(Model!J3>=$C$9,Model!J3-$C$9+1,0) -> 4 | K44: =IF(Model!K3>=$C$9,Model!K3-$C$9+1,0) -> 5 | ... AG44: =IF(Model!AG3>=$C$9,Model!AG3-$C$9+1,0) -> 27
A45: Seebe-Cochrane - Capex | D45: =IF(Model!D3<=4,$B$9*INDEX(Assumptions!$B$24:$E$24,Model!D3),0)*(1+Assumptions!$B$76) -> 0.82 | E45: =IF(Model!E3<=4,$B$9*INDEX(Assumptions!$B$24:$E$24,Model!E3),0)*(1+Assumptions!$B$76) -> 2.46 | F45: =IF(Model!F3<=4,$B$9*INDEX(Assumptions!$B$24:$E$24,Model!F3),0)*(1+Assumptions!$B$76) -> 3.28 | G45: =IF(Model!G3<=4,$B$9*INDEX(Assumptions!$B$24:$E$24,Model!G3),0)*(1+Assumptions!$B$76) -> 1.64 | H45: =IF(Model!H3<=4,$B$9*INDEX(Assumptions!$B$24:$E$24,Model!H3),0)*(1+Assumptions!$B$76) -> 0 | I45: =IF(Model!I3<=4,$B$9*INDEX(Assumptions!$B$24:$E$24,Model!I3),0)*(1+Assumptions!$B$76) -> 0 | J45: =IF(Model!J3<=4,$B$9*INDEX(Assumptions!$B$24:$E$24,Model!J3),0)*(1+Assumptions!$B$76) -> 0 | K45: =IF(Model!K3<=4,$B$9*INDEX(Assumptions!$B$24:$E$24,Model!K3),0)*(1+Assumptions!$B$76) -> 0 | ... AG45: =IF(Model!AG3<=4,$B$9*INDEX(Assumptions!$B$24:$E$24,Model!AG3),0)*(1+Assumptions!$B$76) -> 0
A46: Seebe-Cochrane - Parking Revenue | D46: =$D$9*$E$9*(1+Assumptions!$B$75)*IF(D44<=0,0,INDEX(Assumptions!$B$57:$F$57,MIN(D44,5)))*8760*$F$9*(1+Assumptions!$B$71)^(Model!D3-1)*Assumptions!$B$80/1000000 -> 0 | E46: =$D$9*$E$9*(1+Assumptions!$B$75)*IF(E44<=0,0,INDEX(Assumptions!$B$57:$F$57,MIN(E44,5)))*8760*$F$9*(1+Assumptions!$B$71)^(Model!E3-1)*Assumptions!$B$80/1000000 -> 0 | F46: =$D$9*$E$9*(1+Assumptions!$B$75)*IF(F44<=0,0,INDEX(Assumptions!$B$57:$F$57,MIN(F44,5)))*8760*$F$9*(1+Assumptions!$B$71)^(Model!F3-1)*Assumptions!$B$80/1000000 -> 0 | G46: =$D$9*$E$9*(1+Assumptions!$B$75)*IF(G44<=0,0,INDEX(Assumptions!$B$57:$F$57,MIN(G44,5)))*8760*$F$9*(1+Assumptions!$B$71)^(Model!G3-1)*Assumptions!$B$80/1000000 -> 0.67894477 | H46: =$D$9*$E$9*(1+Assumptions!$B$75)*IF(H44<=0,0,INDEX(Assumptions!$B$57:$F$57,MIN(H44,5)))*8760*$F$9*(1+Assumptions!$B$71)^(Model!H3-1)*Assumptions!$B$80/1000000 -> 0.81190479 | I46: =$D$9*$E$9*(1+Assumptions!$B$75)*IF(I44<=0,0,INDEX(Assumptions!$B$57:$F$57,MIN(I44,5)))*8760*$F$9*(1+Assumptions!$B$71)^(Model!I3-1)*Assumptions!$B$80/1000000 -> 1.0105315 | J46: =$D$9*$E$9*(1+Assumptions!$B$75)*IF(J44<=0,0,INDEX(Assumptions!$B$57:$F$57,MIN(J44,5)))*8760*$F$9*(1+Assumptions!$B$71)^(Model!J3-1)*Assumptions!$B$80/1000000 -> 1.157653 | K46: =$D$9*$E$9*(1+Assumptions!$B$75)*IF(K44<=0,0,INDEX(Assumptions!$B$57:$F$57,MIN(K44,5)))*8760*$F$9*(1+Assumptions!$B$71)^(Model!K3-1)*Assumptions!$B$80/1000000 -> 1.2490466 | ... AG46: =$D$9*$E$9*(1+Assumptions!$B$75)*IF(AG44<=0,0,INDEX(Assumptions!$B$57:$F$57,MIN(AG44,5)))*8760*$F$9*(1+Assumptions!$B$71)^(Model!AG3-1)*Assumptions!$B$80/1000000 -> 2.150323
A47: Seebe-Cochrane - Pod Revenue | D47: =$G$9*(IF(D44<=0,0,IF(D44<=5,$H$9/5*D44,IF(D44<=10,$H$9+($I$9-$H$9)*(D44-5)/5,$I$9))))*365*(1+Assumptions!$B$75)*$J$9*(1+Assumptions!$B$71)^(Model!D3-1)*Assumptions!$B$80/1000000 -> 0 | E47: =$G$9*(IF(E44<=0,0,IF(E44<=5,$H$9/5*E44,IF(E44<=10,$H$9+($I$9-$H$9)*(E44-5)/5,$I$9))))*365*(1+Assumptions!$B$75)*$J$9*(1+Assumptions!$B$71)^(Model!E3-1)*Assumptions!$B$80/1000000 -> 0 | F47: =$G$9*(IF(F44<=0,0,IF(F44<=5,$H$9/5*F44,IF(F44<=10,$H$9+($I$9-$H$9)*(F44-5)/5,$I$9))))*365*(1+Assumptions!$B$75)*$J$9*(1+Assumptions!$B$71)^(Model!F3-1)*Assumptions!$B$80/1000000 -> 0 | G47: =$G$9*(IF(G44<=0,0,IF(G44<=5,$H$9/5*G44,IF(G44<=10,$H$9+($I$9-$H$9)*(G44-5)/5,$I$9))))*365*(1+Assumptions!$B$75)*$J$9*(1+Assumptions!$B$71)^(Model!G3-1)*Assumptions!$B$80/1000000 -> 0.030334797 | H47: =$G$9*(IF(H44<=0,0,IF(H44<=5,$H$9/5*H44,IF(H44<=10,$H$9+($I$9-$H$9)*(H44-5)/5,$I$9))))*365*(1+Assumptions!$B$75)*$J$9*(1+Assumptions!$B$71)^(Model!H3-1)*Assumptions!$B$80/1000000 -> 0.062186335 | I47: =$G$9*(IF(I44<=0,0,IF(I44<=5,$H$9/5*I44,IF(I44<=10,$H$9+($I$9-$H$9)*(I44-5)/5,$I$9))))*365*(1+Assumptions!$B$75)*$J$9*(1+Assumptions!$B$71)^(Model!I3-1)*Assumptions!$B$80/1000000 -> 0.09561149 | J47: =$G$9*(IF(J44<=0,0,IF(J44<=5,$H$9/5*J44,IF(J44<=10,$H$9+($I$9-$H$9)*(J44-5)/5,$I$9))))*365*(1+Assumptions!$B$75)*$J$9*(1+Assumptions!$B$71)^(Model!J3-1)*Assumptions!$B$80/1000000 -> 0.13066904 | K47: =$G$9*(IF(K44<=0,0,IF(K44<=5,$H$9/5*K44,IF(K44<=10,$H$9+($I$9-$H$9)*(K44-5)/5,$I$9))))*365*(1+Assumptions!$B$75)*$J$9*(1+Assumptions!$B$71)^(Model!K3-1)*Assumptions!$B$80/1000000 -> 0.1674197 | ... AG47: =$G$9*(IF(AG44<=0,0,IF(AG44<=5,$H$9/5*AG44,IF(AG44<=10,$H$9+($I$9-$H$9)*(AG44-5)/5,$I$9))))*365*(1+Assumptions!$B$75)*$J$9*(1+Assumptions!$B$71)^(Model!AG3-1)*Assumptions!$B$80/1000000 -> 0.49409995
...

Sheet Model
A1: MODEL - 30 YEAR CASH FLOW (all figures $M unless noted)
A3: Year # | D3: 1 | E3: 2 | F3: 3 | G3: 4 | H3: 5 | I3: 6 | J3: 7 | K3: 8 | L3: 9 | M3: 10 | N3: 11 | O3: 12 | P3: 13 | Q3: 14 | R3: 15 | S3: 16 | T3: 17 | U3: 18 | V3: 19 | W3: 20 | X3: 21 | Y3: 22 | Z3: 23 | AA3: 24 | AB3: 25 | AC3: 26 | AD3: 27 | AE3: 28 | AF3: 29 | AG3: 30
A4: Calendar Year | D4: =Assumptions!$B$6+D3-1 -> 2027 | E4: =Assumptions!$B$6+E3-1 -> 2028 | F4: =Assumptions!$B$6+F3-1 -> 2029 | G4: =Assumptions!$B$6+G3-1 -> 2030 | H4: =Assumptions!$B$6+H3-1 -> 2031 | I4: =Assumptions!$B$6+I3-1 -> 2032 | J4: =Assumptions!$B$6+J3-1 -> 2033 | K4: =Assumptions!$B$6+K3-1 -> 2034 | ... AG4: =Assumptions!$B$6+AG3-1 -> 2056
A5: Mega Hub - years since opening | D5: =IF(D3>=Assumptions!$B$9,D3-Assumptions!$B$9+1,0) -> 0 | E5: =IF(E3>=Assumptions!$B$9,E3-Assumptions!$B$9+1,0) -> 0 | F5: =IF(F3>=Assumptions!$B$9,F3-Assumptions!$B$9+1,0) -> 1 | G5: =IF(G3>=Assumptions!$B$9,G3-Assumptions!$B$9+1,0) -> 2 | H5: =IF(H3>=Assumptions!$B$9,H3-Assumptions!$B$9+1,0) -> 3 | I5: =IF(I3>=Assumptions!$B$9,I3-Assumptions!$B$9+1,0) -> 4 | J5: =IF(J3>=Assumptions!$B$9,J3-Assumptions!$B$9+1,0) -> 5 | K5: =IF(K3>=Assumptions!$B$9,K3-Assumptions!$B$9+1,0) -> 6 | ... AG5: =IF(AG3>=Assumptions!$B$9,AG3-Assumptions!$B$9+1,0) -> 28
A6: Regional/Infill - years since opening | D6: =IF(D3>=Assumptions!$B$10,D3-Assumptions!$B$10+1,0) -> 0 | E6: =IF(E3>=Assumptions!$B$10,E3-Assumptions!$B$10+1,0) -> 0 | F6: =IF(F3>=Assumptions!$B$10,F3-Assumptions!$B$10+1,0) -> 0 | G6: =IF(G3>=Assumptions!$B$10,G3-Assumptions!$B$10+1,0) -> 1 | H6: =IF(H3>=Assumptions!$B$10,H3-Assumptions!$B$10+1,0) -> 2 | I6: =IF(I3>=Assumptions!$B$10,I3-Assumptions!$B$10+1,0) -> 3 | J6: =IF(J3>=Assumptions!$B$10,J3-Assumptions!$B$10+1,0) -> 4 | K6: =IF(K3>=Assumptions!$B$10,K3-Assumptions!$B$10+1,0) -> 5 | ... AG6: =IF(AG3>=Assumptions!$B$10,AG3-Assumptions!$B$10+1,0) -> 27
A8: CAPEX ($M)
A10: Mega Hub capex | D10: =IF(D3<=4,Assumptions!$B$15*Assumptions!$C$15*INDEX(Assumptions!$B$23:$E$23,D3),0)*(1+Assumptions!$B$76) -> 10.6 | E10: =IF(E3<=4,Assumptions!$B$15*Assumptions!$C$15*INDEX(Assumptions!$B$23:$E$23,E3),0)*(1+Assumptions!$B$76) -> 21.2 | F10: =IF(F3<=4,Assumptions!$B$15*Assumptions!$C$15*INDEX(Assumptions!$B$23:$E$23,F3),0)*(1+Assumptions!$B$76) -> 21.2 | G10: =IF(G3<=4,Assumptions!$B$15*Assumptions!$C$15*INDEX(Assumptions!$B$23:$E$23,G3),0)*(1+Assumptions!$B$76) -> 0 | H10: =IF(H3<=4,Assumptions!$B$15*Assumptions!$C$15*INDEX(Assumptions!$B$23:$E$23,H3),0)*(1+Assumptions!$B$76) -> 0 | I10: =IF(I3<=4,Assumptions!$B$15*Assumptions!$C$15*INDEX(Assumptions!$B$23:$E$23,I3),0)*(1+Assumptions!$B$76) -> 0 | J10: =IF(J3<=4,Assumptions!$B$15*Assumptions!$C$15*INDEX(Assumptions!$B$23:$E$23,J3),0)*(1+Assumptions!$B$76) -> 0 | K10: =IF(K3<=4,Assumptions!$B$15*Assumptions!$C$15*INDEX(Assumptions!$B$23:$E$23,K3),0)*(1+Assumptions!$B$76) -> 0 | ... AG10: =IF(AG3<=4,Assumptions!$B$15*Assumptions!$C$15*INDEX(Assumptions!$B$23:$E$23,AG3),0)*(1+Assumptions!$B$76) -> 0
A11: Regional capex (3 sites) | D11: =IF(D3<=4,Assumptions!$B$16*Assumptions!$C$16*INDEX(Assumptions!$B$24:$E$24,D3),0)*(1+Assumptions!$B$76) -> 5.01 | E11: =IF(E3<=4,Assumptions!$B$16*Assumptions!$C$16*INDEX(Assumptions!$B$24:$E$24,E3),0)*(1+Assumptions!$B$76) -> 15.03 | F11: =IF(F3<=4,Assumptions!$B$16*Assumptions!$C$16*INDEX(Assumptions!$B$24:$E$24,F3),0)*(1+Assumptions!$B$76) -> 20.04 | G11: =IF(G3<=4,Assumptions!$B$16*Assumptions!$C$16*INDEX(Assumptions!$B$24:$E$24,G3),0)*(1+Assumptions!$B$76) -> 10.02 | H11: =IF(H3<=4,Assumptions!$B$16*Assumptions!$C$16*INDEX(Assumptions!$B$24:$E$24,H3),0)*(1+Assumptions!$B$76) -> 0 | I11: =IF(I3<=4,Assumptions!$B$16*Assumptions!$C$16*INDEX(Assumptions!$B$24:$E$24,I3),0)*(1+Assumptions!$B$76) -> 0 | J11: =IF(J3<=4,Assumptions!$B$16*Assumptions!$C$16*INDEX(Assumptions!$B$24:$E$24,J3),0)*(1+Assumptions!$B$76) -> 0 | K11: =IF(K3<=4,Assumptions!$B$16*Assumptions!$C$16*INDEX(Assumptions!$B$24:$E$24,K3),0)*(1+Assumptions!$B$76) -> 0 | ... AG11: =IF(AG3<=4,Assumptions!$B$16*Assumptions!$C$16*INDEX(Assumptions!$B$24:$E$24,AG3),0)*(1+Assumptions!$B$76) -> 0
A12: Infill capex (4 sites) | D12: =IF(D3<=4,Assumptions!$B$17*Assumptions!$C$17*INDEX(Assumptions!$B$24:$E$24,D3),0)*(1+Assumptions!$B$76) -> 3.14 | E12: =IF(E3<=4,Assumptions!$B$17*Assumptions!$C$17*INDEX(Assumptions!$B$24:$E$24,E3),0)*(1+Assumptions!$B$76) -> 9.42 | F12: =IF(F3<=4,Assumptions!$B$17*Assumptions!$C$17*INDEX(Assumptions!$B$24:$E$24,F3),0)*(1+Assumptions!$B$76) -> 12.56 | G12: =IF(G3<=4,Assumptions!$B$17*Assumptions!$C$17*INDEX(Assumptions!$B$24:$E$24,G3),0)*(1+Assumptions!$B$76) -> 6.28 | H12: =IF(H3<=4,Assumptions!$B$17*Assumptions!$C$17*INDEX(Assumptions!$B$24:$E$24,H3),0)*(1+Assumptions!$B$76) -> 0 | I12: =IF(I3<=4,Assumptions!$B$17*Assumptions!$C$17*INDEX(Assumptions!$B$24:$E$24,I3),0)*(1+Assumptions!$B$76) -> 0 | J12: =IF(J3<=4,Assumptions!$B$17*Assumptions!$C$17*INDEX(Assumptions!$B$24:$E$24,J3),0)*(1+Assumptions!$B$76) -> 0 | K12: =IF(K3<=4,Assumptions!$B$17*Assumptions!$C$17*INDEX(Assumptions!$B$24:$E$24,K3),0)*(1+Assumptions!$B$76) -> 0 | ... AG12: =IF(AG3<=4,Assumptions!$B$17*Assumptions!$C$17*INDEX(Assumptions!$B$24:$E$24,AG3),0)*(1+Assumptions!$B$76) -> 0
A13: Total Capex | D13: ='Site Detail'!D74 -> 18.74 | E13: ='Site Detail'!E74 -> 45.62 | F13: ='Site Detail'!F74 -> 53.76 | G13: ='Site Detail'!G74 -> 16.28 | H13: ='Site Detail'!H74 -> 0 | I13: ='Site Detail'!I74 -> 0 | J13: ='Site Detail'!J74 -> 0 | K13: ='Site Detail'!K74 -> 0 | ... AG13: ='Site Detail'!AG74 -> 0
A14: Debt Draw (70%) | D14: =D73*Assumptions!$B$62 -> 16.723 | E14: =E73*Assumptions!$B$62 -> 35.539 | F14: =F73*Assumptions!$B$62 -> 41.237 | G14: =G73*Assumptions!$B$62 -> 15.001 | H14: =H73*Assumptions!$B$62 -> 0 | I14: =I73*Assumptions!$B$62 -> 0 | J14: =J73*Assumptions!$B$62 -> 0 | K14: =K73*Assumptions!$B$62 -> 0 | ... AG14: =AG73*Assumptions!$B$62 -> 0
A15: Equity Draw (30%) | D15: =D73*Assumptions!$B$61 -> 7.167 | E15: =E73*Assumptions!$B$61 -> 15.231 | F15: =F73*Assumptions!$B$61 -> 17.673 | G15: =G73*Assumptions!$B$61 -> 6.429 | H15: =H73*Assumptions!$B$61 -> 0 | I15: =I73*Assumptions!$B$61 -> 0 | J15: =J73*Assumptions!$B$61 -> 0 | K15: =K73*Assumptions!$B$61 -> 0 | ... AG15: =AG73*Assumptions!$B$61 -> 0
A17: DEBT SCHEDULE ($M) - interest capitalised during Yrs 1-4 (grace); amortising P+I from Yr 5
A19: Opening balance | D19: 0 | E19: =D25 -> 17.323236 | F19: =E25 -> 55.381393 | G19: =F25 -> 102.0741 | H19: =G25 -> 124.94099 | I19: =H25 -> 122.4468 | J19: =I25 -> 119.77356 | K19: =J25 -> 116.90843 | L19: =K25 -> 113.83762 | ... AG19: =AF25 -> 5.2488643e-14
A20: Draw | D20: =D14 -> 16.723 | E20: =E14 -> 35.539 | F20: =F14 -> 41.237 | G20: =G14 -> 15.001 | H20: =H14 -> 0 | I20: =I14 -> 0 | J20: =J14 -> 0 | K20: =K14 -> 0 | ... AG20: =AG14 -> 0
A21: Interest | D21: =(D19+D20/2)*(Assumptions!$B$63+Assumptions!$B$77/10000) -> 0.60023625 | E21: =(E19+E20/2)*(Assumptions!$B$63+Assumptions!$B$77/10000) -> 2.5191571 | F21: =(F19+F20/2)*(Assumptions!$B$63+Assumptions!$B$77/10000) -> 5.4557066 | G21: =(G19+G20/2)*(Assumptions!$B$63+Assumptions!$B$77/10000) -> 7.8658909 | H21: =(H19+H20/2)*(Assumptions!$B$63+Assumptions!$B$77/10000) -> 8.9689783 | I21: =(I19+I20/2)*(Assumptions!$B$63+Assumptions!$B$77/10000) -> 8.7899311 | J21: =(J19+J20/2)*(Assumptions!$B$63+Assumptions!$B$77/10000) -> 8.5980309 | K21: =(K19+K20/2)*(Assumptions!$B$63+Assumptions!$B$77/10000) -> 8.392355 | ... AG21: =(AG19+AG20/2)*(Assumptions!$B$63+Assumptions!$B$77/10000) -> 3.7679347e-15
A22: Capitalised interest (Yrs 1-4) | D22: =IF(D3<=Assumptions!$B$65,D21,0) -> 0.60023625 | E22: =IF(E3<=Assumptions!$B$65,E21,0) -> 2.5191571 | F22: =IF(F3<=Assumptions!$B$65,F21,0) -> 5.4557066 | G22: =IF(G3<=Assumptions!$B$65,G21,0) -> 7.8658909 | H22: =IF(H3<=Assumptions!$B$65,H21,0) -> 0 | I22: =IF(I3<=Assumptions!$B$65,I21,0) -> 0 | J22: =IF(J3<=Assumptions!$B$65,J21,0) -> 0 | K22: =IF(K3<=Assumptions!$B$65,K21,0) -> 0 | ... AG22: =IF(AG3<=Assumptions!$B$65,AG21,0) -> 0
A23: Scheduled debt service (P+I) | D23: =IF(AND(D3>Assumptions!$B$65,D3<=Assumptions!$B$65+Assumptions!$B$64),-PMT((Assumptions!$B$63+Assumptions!$B$77/10000),Assumptions!$B$64,G25),0) -> 0 | E23: =IF(AND(E3>Assumptions!$B$65,E3<=Assumptions!$B$65+Assumptions!$B$64),-PMT((Assumptions!$B$63+Assumptions!$B$77/10000),Assumptions!$B$64,G25),0) -> 0 | F23: =IF(AND(F3>Assumptions!$B$65,F3<=Assumptions!$B$65+Assumptions!$B$64),-PMT((Assumptions!$B$63+Assumptions!$B$77/10000),Assumptions!$B$64,G25),0) -> 0 | G23: =IF(AND(G3>Assumptions!$B$65,G3<=Assumptions!$B$65+Assumptions!$B$64),-PMT((Assumptions!$B$63+Assumptions!$B$77/10000),Assumptions!$B$64,G25),0) -> 0 | H23: =IF(AND(H3>Assumptions!$B$65,H3<=Assumptions!$B$65+Assumptions!$B$64),-PMT((Assumptions!$B$63+Assumptions!$B$77/10000),Assumptions!$B$64,G25),0) -> 11.463168 | I23: =IF(AND(I3>Assumptions!$B$65,I3<=Assumptions!$B$65+Assumptions!$B$64),-PMT((Assumptions!$B$63+Assumptions!$B$77/10000),Assumptions!$B$64,G25),0) -> 11.463168 | J23: =IF(AND(J3>Assumptions!$B$65,J3<=Assumptions!$B$65+Assumptions!$B$64),-PMT((Assumptions!$B$63+Assumptions!$B$77/10000),Assumptions!$B$64,G25),0) -> 11.463168 | K23: =IF(AND(K3>Assumptions!$B$65,K3<=Assumptions!$B$65+Assumptions!$B$64),-PMT((Assumptions!$B$63+Assumptions!$B$77/10000),Assumptions!$B$64,G25),0) -> 11.463168 | L23: =IF(AND(L3>Assumptions!$B$65,L3<=Assumptions!$B$65+Assumptions!$B$64),-PMT((Assumptions!$B$63+Assumptions!$B$77/10000),Assumptions!$B$64,G25),0) -> 11.463168 | M23: =IF(AND(M3>Assumptions!$B$65,M3<=Assumptions!$B$65+Assumptions!$B$64),-PMT((Assumptions!$B$63+Assumptions!$B$77/10000),Assumptions!$B$64,G25),0) -> 11.463168 | N23: =IF(AND(N3>Assumptions!$B$65,N3<=Assumptions!$B$65+Assumptions!$B$64),-PMT((Assumptions!$B$63+Assumptions!$B$77/10000),Assumptions!$B$64,G25),0) -> 11.463168 | O23: =IF(AND(O3>Assumptions!$B$65,O3<=Assumptions!$B$65+Assumptions!$B$64),-PMT((Assumptions!$B$63+Assumptions!$B$77/10000),Assumptions!$B$64,G25),0) -> 11.463168 | P23: =IF(AND(P3>Assumptions!$B$65,P3<=Assumptions!$B$65+Assumptions!$B$64),-PMT((Assumptions!$B$63+Assumptions!$B$77/10000),Assumptions!$B$64,G25),0) -> 11.463168 | Q23: =IF(AND(Q3>Assumptions!$B$65,Q3<=Assumptions!$B$65+Assumptions!$B$64),-PMT((Assumptions!$B$63+Assumptions!$B$77/10000),Assumptions!$B$64,G25),0) -> 11.463168 | R23: =IF(AND(R3>Assumptions!$B$65,R3<=Assumptions!$B$65+Assumptions!$B$64),-PMT((Assumptions!$B$63+Assumptions!$B$77/10000),Assumptions!$B$64,G25),0) -> 11.463168 | S23: =IF(AND(S3>Assumptions!$B$65,S3<=Assumptions!$B$65+Assumptions!$B$64),-PMT((Assumptions!$B$63+Assumptions!$B$77/10000),Assumptions!$B$64,G25),0) -> 11.463168 | T23: =IF(AND(T3>Assumptions!$B$65,T3<=Assumptions!$B$65+Assumptions!$B$64),-PMT((Assumptions!$B$63+Assumptions!$B$77/10000),Assumptions!$B$64,G25),0) -> 11.463168 | U23: =IF(AND(U3>Assumptions!$B$65,U3<=Assumptions!$B$65+Assumptions!$B$64),-PMT((Assumptions!$B$63+Assumptions!$B$77/10000),Assumptions!$B$64,G25),0) -> 11.463168 | V23: =IF(AND(V3>Assumptions!$B$65,V3<=Assumptions!$B$65+Assumptions!$B$64),-PMT((Assumptions!$B$63+Assumptions!$B$77/10000),Assumptions!$B$64,G25),0) -> 11.463168 | W23: =IF(AND(W3>Assumptions!$B$65,W3<=Assumptions!$B$65+Assumptions!$B$64),-PMT((Assumptions!$B$63+Assumptions!$B$77/10000),Assumptions!$B$64,G25),0) -> 11.463168 | X23: =IF(AND(X3>Assumptions!$B$65,X3<=Assumptions!$B$65+Assumptions!$B$64),-PMT((Assumptions!$B$63+Assumptions!$B$77/10000),Assumptions!$B$64,G25),0) -> 11.463168 | Y23: =IF(AND(Y3>Assumptions!$B$65,Y3<=Assumptions!$B$65+Assumptions!$B$64),-PMT((Assumptions!$B$63+Assumptions!$B$77/10000),Assumptions!$B$64,G25),0) -> 11.463168 | Z23: =IF(AND(Z3>Assumptions!$B$65,Z3<=Assumptions!$B$65+Assumptions!$B$64),-PMT((Assumptions!$B$63+Assumptions!$B$77/10000),Assumptions!$B$64,G25),0) -> 11.463168 | AA23: =IF(AND(AA3>Assumptions!$B$65,AA3<=Assumptions!$B$65+Assumptions!$B$64),-PMT((Assumptions!$B$63+Assumptions!$B$77/10000),Assumptions!$B$64,G25),0) -> 11.463168 | AB23: =IF(AND(AB3>Assumptions!$B$65,AB3<=Assumptions!$B$65+Assumptions!$B$64),-PMT((Assumptions!$B$63+Assumptions!$B$77/10000),Assumptions!$B$64,G25),0) -> 11.463168 | AC23: =IF(AND(AC3>Assumptions!$B$65,AC3<=Assumptions!$B$65+Assumptions!$B$64),-PMT((Assumptions!$B$63+Assumptions!$B$77/10000),Assumptions!$B$64,G25),0) -> 11.463168 | AD23: =IF(AND(AD3>Assumptions!$B$65,AD3<=Assumptions!$B$65+Assumptions!$B$64),-PMT((Assumptions!$B$63+Assumptions!$B$77/10000),Assumptions!$B$64,G25),0) -> 0 | AE23: =IF(AND(AE3>Assumptions!$B$65,AE3<=Assumptions!$B$65+Assumptions!$B$64),-PMT((Assumptions!$B$63+Assumptions!$B$77/10000),Assumptions!$B$64,G25),0) -> 0 | AF23: =IF(AND(AF3>Assumptions!$B$65,AF3<=Assumptions!$B$65+Assumptions!$B$64),-PMT((Assumptions!$B$63+Assumptions!$B$77/10000),Assumptions!$B$64,G25),0) -> 0 | AG23: =IF(AND(AG3>Assumptions!$B$65,AG3<=Assumptions!$B$65+Assumptions!$B$64),-PMT((Assumptions!$B$63+Assumptions!$B$77/10000),Assumptions!$B$64,G25),0) -> 0
A24: Principal repayment | D24: =IF(D3>Assumptions!$B$65,MIN(D19,D23-D21),0) -> 0 | E24: =IF(E3>Assumptions!$B$65,MIN(E19,E23-E21),0) -> 0 | F24: =IF(F3>Assumptions!$B$65,MIN(F19,F23-F21),0) -> 0 | G24: =IF(G3>Assumptions!$B$65,MIN(G19,G23-G21),0) -> 0 | H24: =IF(H3>Assumptions!$B$65,MIN(H19,H23-H21),0) -> 2.4941894 | I24: =IF(I3>Assumptions!$B$65,MIN(I19,I23-I21),0) -> 2.6732366 | J24: =IF(J3>Assumptions!$B$65,MIN(J19,J23-J21),0) -> 2.8651368 | K24: =IF(K3>Assumptions!$B$65,MIN(K19,K23-K21),0) -> 3.0708127 | ... AG24: =IF(AG3>Assumptions!$B$65,MIN(AG19,AG23-AG21),0) -> -3.7679347e-15
A25: Closing balance | D25: =MAX(0,D19+D20+D22-D24) -> 17.323236 | E25: =MAX(0,E19+E20+E22-E24) -> 55.381393 | F25: =MAX(0,F19+F20+F22-F24) -> 102.0741 | G25: =MAX(0,G19+G20+G22-G24) -> 124.94099 | H25: =MAX(0,H19+H20+H22-H24) -> 122.4468 | I25: =MAX(0,I19+I20+I22-I24) -> 119.77356 | J25: =MAX(0,J19+J20+J22-J24) -> 116.90843 | K25: =MAX(0,K19+K20+K22-K24) -> 113.83762 | ... AG25: =MAX(0,AG19+AG20+AG22-AG24) -> 5.6256578e-14
A27: COMMERCIAL REVENUE ($M)
A29: Parking - Mega Hub | D29: =Assumptions!$B$15*Assumptions!$B$29*Assumptions!$C$29*(1+Assumptions!$B$75)*IF(D5<=0,0,INDEX(Assumptions!$B$57:$F$57,MIN(D5,5)))*8760*Assumptions!$D$29*(1+Assumptions!$B$71)^(D3-1)/1000000*Assumptions!$B$80 -> 0 | E29: =Assumptions!$B$15*Assumptions!$B$29*Assumptions!$C$29*(1+Assumptions!$B$75)*IF(E5<=0,0,INDEX(Assumptions!$B$57:$F$57,MIN(E5,5)))*8760*Assumptions!$D$29*(1+Assumptions!$B$71)^(E3-1)/1000000*Assumptions!$B$80 -> 0 | F29: =Assumptions!$B$15*Assumptions!$B$29*Assumptions!$C$29*(1+Assumptions!$B$75)*IF(F5<=0,0,INDEX(Assumptions!$B$57:$F$57,MIN(F5,5)))*8760*Assumptions!$D$29*(1+Assumptions!$B$71)^(F3-1)/1000000*Assumptions!$B$80 -> 5.4410208 | G29: =Assumptions!$B$15*Assumptions!$B$29*Assumptions!$C$29*(1+Assumptions!$B$75)*IF(G5<=0,0,INDEX(Assumptions!$B$57:$F$57,MIN(G5,5)))*8760*Assumptions!$D$29*(1+Assumptions!$B$71)^(G3-1)/1000000*Assumptions!$B$80 -> 6.506554 | H29: =Assumptions!$B$15*Assumptions!$B$29*Assumptions!$C$29*(1+Assumptions!$B$75)*IF(H5<=0,0,INDEX(Assumptions!$B$57:$F$57,MIN(H5,5)))*8760*Assumptions!$D$29*(1+Assumptions!$B$71)^(H3-1)/1000000*Assumptions!$B$80 -> 8.098336 | I29: =Assumptions!$B$15*Assumptions!$B$29*Assumptions!$C$29*(1+Assumptions!$B$75)*IF(I5<=0,0,INDEX(Assumptions!$B$57:$F$57,MIN(I5,5)))*8760*Assumptions!$D$29*(1+Assumptions!$B$71)^(I3-1)/1000000*Assumptions!$B$80 -> 9.2773584 | J29: =Assumptions!$B$15*Assumptions!$B$29*Assumptions!$C$29*(1+Assumptions!$B$75)*IF(J5<=0,0,INDEX(Assumptions!$B$57:$F$57,MIN(J5,5)))*8760*Assumptions!$D$29*(1+Assumptions!$B$71)^(J3-1)/1000000*Assumptions!$B$80 -> 10.009781 | K29: =Assumptions!$B$15*Assumptions!$B$29*Assumptions!$C$29*(1+Assumptions!$B$75)*IF(K5<=0,0,INDEX(Assumptions!$B$57:$F$57,MIN(K5,5)))*8760*Assumptions!$D$29*(1+Assumptions!$B$71)^(K3-1)/1000000*Assumptions!$B$80 -> 10.260026 | ... AG29: =Assumptions!$B$15*Assumptions!$B$29*Assumptions!$C$29*(1+Assumptions!$B$75)*IF(AG5<=0,0,INDEX(Assumptions!$B$57:$F$57,MIN(AG5,5)))*8760*Assumptions!$D$29*(1+Assumptions!$B$71)^(AG3-1)/1000000*Assumptions!$B$80 -> 17.663367
A30: Parking - Regional (3) | D30: =Assumptions!$B$16*Assumptions!$B$30*Assumptions!$C$30*(1+Assumptions!$B$75)*IF(D6<=0,0,INDEX(Assumptions!$B$57:$F$57,MIN(D6,5)))*8760*Assumptions!$D$30*(1+Assumptions!$B$71)^(D3-1)/1000000*Assumptions!$B$80 -> 0 | E30: =Assumptions!$B$16*Assumptions!$B$30*Assumptions!$C$30*(1+Assumptions!$B$75)*IF(E6<=0,0,INDEX(Assumptions!$B$57:$F$57,MIN(E6,5)))*8760*Assumptions!$D$30*(1+Assumptions!$B$71)^(E3-1)/1000000*Assumptions!$B$80 -> 0 | F30: =Assumptions!$B$16*Assumptions!$B$30*Assumptions!$C$30*(1+Assumptions!$B$75)*IF(F6<=0,0,INDEX(Assumptions!$B$57:$F$57,MIN(F6,5)))*8760*Assumptions!$D$30*(1+Assumptions!$B$71)^(F3-1)/1000000*Assumptions!$B$80 -> 0 | G30: =Assumptions!$B$16*Assumptions!$B$30*Assumptions!$C$30*(1+Assumptions!$B$75)*IF(G6<=0,0,INDEX(Assumptions!$B$57:$F$57,MIN(G6,5)))*8760*Assumptions!$D$30*(1+Assumptions!$B$71)^(G3-1)/1000000*Assumptions!$B$80 -> 5.4558062 | H30: =Assumptions!$B$16*Assumptions!$B$30*Assumptions!$C$30*(1+Assumptions!$B$75)*IF(H6<=0,0,INDEX(Assumptions!$B$57:$F$57,MIN(H6,5)))*8760*Assumptions!$D$30*(1+Assumptions!$B$71)^(H3-1)/1000000*Assumptions!$B$80 -> 6.5242349 | I30: =Assumptions!$B$16*Assumptions!$B$30*Assumptions!$C$30*(1+Assumptions!$B$75)*IF(I6<=0,0,INDEX(Assumptions!$B$57:$F$57,MIN(I6,5)))*8760*Assumptions!$D$30*(1+Assumptions!$B$71)^(I3-1)/1000000*Assumptions!$B$80 -> 8.1203423 | J30: =Assumptions!$B$16*Assumptions!$B$30*Assumptions!$C$30*(1+Assumptions!$B$75)*IF(J6<=0,0,INDEX(Assumptions!$B$57:$F$57,MIN(J6,5)))*8760*Assumptions!$D$30*(1+Assumptions!$B$71)^(J3-1)/1000000*Assumptions!$B$80 -> 9.3025687 | K30: =Assumptions!$B$16*Assumptions!$B$30*Assumptions!$C$30*(1+Assumptions!$B$75)*IF(K6<=0,0,INDEX(Assumptions!$B$57:$F$57,MIN(K6,5)))*8760*Assumptions!$D$30*(1+Assumptions!$B$71)^(K3-1)/1000000*Assumptions!$B$80 -> 10.036982 | ... AG30: =Assumptions!$B$16*Assumptions!$B$30*Assumptions!$C$30*(1+Assumptions!$B$75)*IF(AG6<=0,0,INDEX(Assumptions!$B$57:$F$57,MIN(AG6,5)))*8760*Assumptions!$D$30*(1+Assumptions!$B$71)^(AG3-1)/1000000*Assumptions!$B$80 -> 17.279381
