Workbook

Sheet Stats
A1: Stats | C1: As of Apr 20
A2: Reviewer | B2: Total Jobs | C2: Assigned | D2: Jobs to Assign | E2: Stuck Jobs | F2: Actual Jobs Reviewed | G2: Attempts submitted to the agent | H2: Turn 0 Assigned on Slack | I2: Attempts Reviewed | J2: Threads Left to Review | K2: Turn 0 Success | L2: Overall Pass Rate | M2: Remaining Evals to process for Turn 1 | N2: Turn 1 Change Requested | O2: Review Ready - Turn 1 - Assigned in Slack | P2: Attempts Reviewed Turn 1 | Q2: Turn 1 Success | R2: Overall Pass Rate Turn 1 | S2: Turn 2 Change Requested | T2: Review Ready - Turn 2 - Assigned in Slack | U2: Attempts Reviewed Turn 2 | V2: Turn 2 Success
A3: Sanjeev | B3: =COUNTIF(assignments!B:B, A3) -> 26 | C3: =IFERROR(__xludf.DUMMYFUNCTION("IFERROR(COUNTUNIQUE(FILTER(job_status!A:A, job_status!C:C=A28)),0)"),26.0) -> 26 | D3: =B3-C3 -> 0 | E3: 0 | F3: =IFERROR(__xludf.DUMMYFUNCTION("IFERROR(COUNTUNIQUE(FILTER(job_status!A:A, job_status!C:C = A28, job_status!E:E = ""up:Reviewed"")), 0)"),26.0) -> 26 | G3: =IFERROR(__xludf.DUMMYFUNCTION("IFERROR(ROWS(UNIQUE(FILTER(job_status!D:D, job_status!C:C=A28, job_status!E:E=""up:Submitted""))), 0)"),78.0) -> 78 | H3: =IFERROR(__xludf.DUMMYFUNCTION("IFERROR(ROWS(UNIQUE(FILTER(job_status!D:D, job_status!C:C=A28, job_status!E:E=""up:InReview"", job_status!F:F=0))), 0)"),78.0) -> 78 | I3: =COUNTIFS(job_status!C:C, A28, job_status!E:E, "up:Reviewed", job_status!F:F,0) -> 78 | J3: =H3 - I3 -> 0 | K3: =IFERROR(__xludf.DUMMYFUNCTION("IFERROR(ROWS(UNIQUE(FILTER(job_status!D:D, job_status!C:C=A28, job_status!E:E=""up:Success"", job_status!F:F=0))), 0)"),23.0) -> 23 | L3: =K3/I3 -> 0.29487179 | M3: =(I3 - K3) - N3 -> 0 | N3: =IFERROR(__xludf.DUMMYFUNCTION("IFERROR(ROWS(UNIQUE(FILTER(job_status!D:D, job_status!C:C=A28, job_status!E:E=""up:ChangeRequested"", job_status!F:F=1))), 0)"),55.0) -> 55 | O3: =IFERROR(__xludf.DUMMYFUNCTION("IFERROR(ROWS(UNIQUE(FILTER(job_status!D:D, job_status!C:C=A28, job_status!E:E=""up:InReview"", job_status!F:F=1))), 0)"),55.0) -> 55 | P3: =COUNTIFS(job_status!C:C, A28, job_status!E:E, "up:Reviewed", job_status!F:F,1) -> 55 | Q3: =IFERROR(__xludf.DUMMYFUNCTION("IFERROR(ROWS(UNIQUE(FILTER(job_status!D:D, job_status!C:C=A28, job_status!E:E=""up:Success"", job_status!F:F=1))), 0)"),15.0) -> 15 | R3: =Q3/P3 -> 0.27272727 | S3: =IFERROR(__xludf.DUMMYFUNCTION("IFERROR(ROWS(UNIQUE(FILTER(job_status!D:D, job_status!C:C=A28, job_status!E:E=""up:ChangeRequested"", job_status!F:F=2))), 0)"),40.0) -> 40 | T3: =IFERROR(__xludf.DUMMYFUNCTION("IFERROR(ROWS(UNIQUE(FILTER(job_status!D:D, job_status!C:C=A28, job_status!E:E=""up:InReview"", job_status!F:F=2))), 0)"),40.0) -> 40 | U3: =COUNTIFS(job_status!C:C, A28, job_status!E:E, "up:Reviewed", job_status!F:F,2) -> 40 | V3: =IFERROR(__xludf.DUMMYFUNCTION("IFERROR(ROWS(UNIQUE(FILTER(job_status!D:D, job_status!C:C=A28, job_status!E:E=""up:Success"", job_status!F:F=2))), 0)"),17.0) -> 17
A4: Solomon | B4: =COUNTIF(assignments!B:B, A4) -> 30 | C4: =IFERROR(__xludf.DUMMYFUNCTION("IFERROR(COUNTUNIQUE(FILTER(job_status!A:A, job_status!C:C=A29)),0)"),28.0) -> 28 | D4: =B4-C4 -> 2 | E4: 0 | F4: =IFERROR(__xludf.DUMMYFUNCTION("COUNTUNIQUE(FILTER(job_status!A:A, job_status!C:C = A29, job_status!E:E = ""up:Reviewed""))"),27.0) -> 27 | G4: =IFERROR(__xludf.DUMMYFUNCTION("IFERROR(ROWS(UNIQUE(FILTER(job_status!D:D, job_status!C:C=A29, job_status!E:E=""up:Submitted""))), 0)"),84.0) -> 84 | H4: =IFERROR(__xludf.DUMMYFUNCTION("IFERROR(ROWS(UNIQUE(FILTER(job_status!D:D, job_status!C:C=A29, job_status!E:E=""up:InReview"", job_status!F:F=0))), 0)"),81.0) -> 81 | I4: =COUNTIFS(job_status!C:C, A29, job_status!E:E, "up:Reviewed", job_status!F:F,0) -> 81 | J4: =H4 - I4 -> 0 | K4: =IFERROR(__xludf.DUMMYFUNCTION("IFERROR(ROWS(UNIQUE(FILTER(job_status!D:D, job_status!C:C=A29, job_status!E:E=""up:Success"", job_status!F:F=0))), 0)"),47.0) -> 47 | L4: =K4/I4 -> 0.58024691 | M4: =(I4 - K4) - N4 -> 0 | N4: =IFERROR(__xludf.DUMMYFUNCTION("IFERROR(ROWS(UNIQUE(FILTER(job_status!D:D, job_status!C:C=A29, job_status!E:E=""up:ChangeRequested"", job_status!F:F=1))), 0)"),34.0) -> 34 | O4: =IFERROR(__xludf.DUMMYFUNCTION("IFERROR(ROWS(UNIQUE(FILTER(job_status!D:D, job_status!C:C=A29, job_status!E:E=""up:InReview"", job_status!F:F=1))), 0)"),34.0) -> 34 | P4: =COUNTIFS(job_status!C:C, A29, job_status!E:E, "up:Reviewed", job_status!F:F,1) -> 34 | Q4: =IFERROR(__xludf.DUMMYFUNCTION("IFERROR(ROWS(UNIQUE(FILTER(job_status!D:D, job_status!C:C=A29, job_status!E:E=""up:Success"", job_status!F:F=1))), 0)"),23.0) -> 23 | R4: =Q4/P4 -> 0.67647059 | S4: =IFERROR(__xludf.DUMMYFUNCTION("IFERROR(ROWS(UNIQUE(FILTER(job_status!D:D, job_status!C:C=A29, job_status!E:E=""up:ChangeRequested"", job_status!F:F=2))), 0)"),11.0) -> 11 | T4: =IFERROR(__xludf.DUMMYFUNCTION("IFERROR(ROWS(UNIQUE(FILTER(job_status!D:D, job_status!C:C=A29, job_status!E:E=""up:InReview"", job_status!F:F=2))), 0)"),11.0) -> 11 | U4: =COUNTIFS(job_status!C:C, A29, job_status!E:E, "up:Reviewed", job_status!F:F,2) -> 11 | V4: =IFERROR(__xludf.DUMMYFUNCTION("IFERROR(ROWS(UNIQUE(FILTER(job_status!D:D, job_status!C:C=A29, job_status!E:E=""up:Success"", job_status!F:F=2))), 0)"),6.0) -> 6
A5: Ghulam | B5: =COUNTIF(assignments!B:B, A5) -> 28 | C5: =IFERROR(__xludf.DUMMYFUNCTION("IFERROR(COUNTUNIQUE(FILTER(job_status!A:A, job_status!C:C=A30)),0)"),28.0) -> 28 | D5: =B5-C5 -> 0 | E5: 0 | F5: =IFERROR(__xludf.DUMMYFUNCTION("COUNTUNIQUE(FILTER(job_status!A:A, job_status!C:C = A30, job_status!E:E = ""up:Reviewed""))"),28.0) -> 28 | G5: =IFERROR(__xludf.DUMMYFUNCTION("IFERROR(ROWS(UNIQUE(FILTER(job_status!D:D, job_status!C:C=A30, job_status!E:E=""up:Submitted""))), 0)"),84.0) -> 84 | H5: =IFERROR(__xludf.DUMMYFUNCTION("IFERROR(ROWS(UNIQUE(FILTER(job_status!D:D, job_status!C:C=A30, job_status!E:E=""up:InReview"", job_status!F:F=0))), 0)"),84.0) -> 84 | I5: =COUNTIFS(job_status!C:C, A30, job_status!E:E, "up:Reviewed", job_status!F:F,0) -> 84 | J5: =H5 - I5 -> 0 | K5: =IFERROR(__xludf.DUMMYFUNCTION("IFERROR(ROWS(UNIQUE(FILTER(job_status!D:D, job_status!C:C=A30, job_status!E:E=""up:Success"", job_status!F:F=0))), 0)"),23.0) -> 23 | L5: =K5/I5 -> 0.27380952 | M5: =(I5 - K5) - N5 -> 0 | N5: =IFERROR(__xludf.DUMMYFUNCTION("IFERROR(ROWS(UNIQUE(FILTER(job_status!D:D, job_status!C:C=A30, job_status!E:E=""up:ChangeRequested"", job_status!F:F=1))), 0)"),61.0) -> 61 | O5: =IFERROR(__xludf.DUMMYFUNCTION("IFERROR(ROWS(UNIQUE(FILTER(job_status!D:D, job_status!C:C=A30, job_status!E:E=""up:InReview"", job_status!F:F=1))), 0)"),61.0) -> 61 | P5: =COUNTIFS(job_status!C:C, A30, job_status!E:E, "up:Reviewed", job_status!F:F,1) -> 61 | Q5: =IFERROR(__xludf.DUMMYFUNCTION("IFERROR(ROWS(UNIQUE(FILTER(job_status!D:D, job_status!C:C=A30, job_status!E:E=""up:Success"", job_status!F:F=1))), 0)"),25.0) -> 25 | R5: =Q5/P5 -> 0.40983607 | S5: =IFERROR(__xludf.DUMMYFUNCTION("IFERROR(ROWS(UNIQUE(FILTER(job_status!D:D, job_status!C:C=A30, job_status!E:E=""up:ChangeRequested"", job_status!F:F=2))), 0)"),36.0) -> 36 | T5: =IFERROR(__xludf.DUMMYFUNCTION("IFERROR(ROWS(UNIQUE(FILTER(job_status!D:D, job_status!C:C=A30, job_status!E:E=""up:InReview"", job_status!F:F=2))), 0)"),36.0) -> 36 | U5: =COUNTIFS(job_status!C:C, A30, job_status!E:E, "up:Reviewed", job_status!F:F,2) -> 36 | V5: =IFERROR(__xludf.DUMMYFUNCTION("IFERROR(ROWS(UNIQUE(FILTER(job_status!D:D, job_status!C:C=A30, job_status!E:E=""up:Success"", job_status!F:F=2))), 0)"),12.0) -> 12
A6: Youssef | B6: =COUNTIF(assignments!B:B, A6) -> 23 | C6: =IFERROR(__xludf.DUMMYFUNCTION("IFERROR(COUNTUNIQUE(FILTER(job_status!A:A, job_status!C:C=A31)),0)"),23.0) -> 23 | D6: =B6-C6 -> 0 | E6: 0 | F6: =IFERROR(__xludf.DUMMYFUNCTION("COUNTUNIQUE(FILTER(job_status!A:A, job_status!C:C = A31, job_status!E:E = ""up:Reviewed""))"),23.0) -> 23 | G6: =IFERROR(__xludf.DUMMYFUNCTION("IFERROR(ROWS(UNIQUE(FILTER(job_status!D:D, job_status!C:C=A31, job_status!E:E=""up:Submitted""))), 0)"),69.0) -> 69 | H6: =IFERROR(__xludf.DUMMYFUNCTION("IFERROR(ROWS(UNIQUE(FILTER(job_status!D:D, job_status!C:C=A31, job_status!E:E=""up:InReview"", job_status!F:F=0))), 0)"),69.0) -> 69 | I6: =COUNTIFS(job_status!C:C, A31, job_status!E:E, "up:Reviewed", job_status!F:F,0) -> 69 | J6: =H6 - I6 -> 0 | K6: =IFERROR(__xludf.DUMMYFUNCTION("IFERROR(ROWS(UNIQUE(FILTER(job_status!D:D, job_status!C:C=A31, job_status!E:E=""up:Success"", job_status!F:F=0))), 0)"),33.0) -> 33 | L6: =K6/I6 -> 0.47826087 | M6: =(I6 - K6) - N6 -> 0 | N6: =IFERROR(__xludf.DUMMYFUNCTION("IFERROR(ROWS(UNIQUE(FILTER(job_status!D:D, job_status!C:C=A31, job_status!E:E=""up:ChangeRequested"", job_status!F:F=1))), 0)"),36.0) -> 36 | O6: =IFERROR(__xludf.DUMMYFUNCTION("IFERROR(ROWS(UNIQUE(FILTER(job_status!D:D, job_status!C:C=A31, job_status!E:E=""up:InReview"", job_status!F:F=1))), 0)"),36.0) -> 36 | P6: =COUNTIFS(job_status!C:C, A31, job_status!E:E, "up:Reviewed", job_status!F:F,1) -> 36 | Q6: =IFERROR(__xludf.DUMMYFUNCTION("IFERROR(ROWS(UNIQUE(FILTER(job_status!D:D, job_status!C:C=A31, job_status!E:E=""up:Success"", job_status!F:F=1))), 0)"),12.0) -> 12 | R6: =Q6/P6 -> 0.33333333 | S6: =IFERROR(__xludf.DUMMYFUNCTION("IFERROR(ROWS(UNIQUE(FILTER(job_status!D:D, job_status!C:C=A31, job_status!E:E=""up:ChangeRequested"", job_status!F:F=2))), 0)"),24.0) -> 24 | T6: =IFERROR(__xludf.DUMMYFUNCTION("IFERROR(ROWS(UNIQUE(FILTER(job_status!D:D, job_status!C:C=A31, job_status!E:E=""up:InReview"", job_status!F:F=2))), 0)"),24.0) -> 24 | U6: =COUNTIFS(job_status!C:C, A31, job_status!E:E, "up:Reviewed", job_status!F:F,2) -> 24 | V6: =IFERROR(__xludf.DUMMYFUNCTION("IFERROR(ROWS(UNIQUE(FILTER(job_status!D:D, job_status!C:C=A31, job_status!E:E=""up:Success"", job_status!F:F=2))), 0)"),13.0) -> 13
A8: Totals | B8: =sum(B3:B6) -> 107 | C8: =sum(C3:C6) -> 105 | D8: =sum(D3:D6) -> 2 | E8: =sum(E3:E6) -> 0 | F8: =sum(F3:F6) -> 104 | G8: =sum(G3:G6) -> 315 | H8: =sum(H3:H6) -> 312 | I8: =sum(I3:I6) -> 312 | ... K8: =sum(K3:K6) -> 126 | L8: =K8/I8 -> 0.40384615 | M8: =sum(M3:M6) -> 0 | N8: =sum(N3:N6) -> 186 | O8: =sum(O3:O6) -> 186 | P8: =sum(P3:P6) -> 186 | Q8: =sum(Q3:Q6) -> 75 | R8: =Q8/P8 -> 0.40322581 | S8: =sum(S3:S6) -> 111 | T8: =sum(T3:T6) -> 111 | U8: =sum(U3:U6) -> 111 | V8: =sum(V3:V6) -> 48
E9: =E8/B8 -> 0
K12: Assignments Faling M1 | L12: Name | M12: Turn 1 Reviews Pending | N12: Turn 2 Reviews Pending
K13: =COUNTIF(M5_submission_fails!F:F, "No") -> 0 | L13: Sanjeev | M13: =(O3 - P3) -> 0 | N13: =(T3 - U3) -> 0
L14: Solomon | M14: =(O4 - P4) -> 0 | N14: =(T4 - U4) -> 0
L15: Ghulam | M15: =(O5 - P5) -> 0 | N15: =(T5 - U5) -> 0
L16: Youssef | M16: =(O6 - P6) -> 0 | N16: =(T6 - U6) -> 0
L17: Remaining | M17: =sum(M13:M16) -> 0 | N17: =sum(N13:N16) -> 0
L18: Assuming all remaining turn 1 reviews fail, they will have to be reviewed in turn 2. That will add to the existing pending reviews in turn 2 | M18: =2*M17 + N17 -> 0
L19: Assuming same remaining succes percentage | M19: =R8*M17*2 + N17 -> 0
L20: Time per review (in minutes) | M20: =67*0.6*2 + N17 -> 80.4
L21: Max Time (hours) | M21: =M18*20/60 -> 0
L22: Max Time percentage(hours) | M22: =M19*20/60 -> 0
L23: Sanjeev | M23: =(2*M13+N13)*20/60 -> 0 | N23: =(2*M13*0.69+N13)*20/60 -> 0
L24: Solomon | M24: =(2*M14+N14)*20/60 -> 0 | N24: =(2*M14*0.69+N14)*20/60 -> 0
L25: Ghulam | M25: =(2*M15+N15)*20/60 -> 0 | N25: =(2*M15*0.69+N15)*20/60 -> 0
L26: Youssef | M26: =(2*M16+N16)*20/60 -> 0 | N26: =(2*M16*0.69+N16)*20/60 -> 0
A27: Slack Helper for assigned DO NOT TOUCH | M27: =sum(M23:M26) -> 0 | N27: =(2*M17*0.69+N17)*20/60 -> 0
A28: {=INDEX(assignments!C:C, MATCH(A3, assignments!B:B, 0))} -> U0ARQUUJXBM | L28: Darvin (assuming 3 hours and 4 reviews per hour) | M28: 12
A29: {=INDEX(assignments!C:C, MATCH(A4, assignments!B:B, 0))} -> U0ASA7SCECR | L29: Karthik (assuming 9 hours and 4 reveiws per hour) | M29: 36
A30: {=INDEX(assignments!C:C, MATCH(A5, assignments!B:B, 0))} -> U0ASRJTQSPJ | L30: Nikhil (assuming 4 hours at 4 reviews per hour) | M30: 16
A31: {=INDEX(assignments!C:C, MATCH(A6, assignments!B:B, 0))} -> U0ARV8X2JDU | M31: =sum(M28:M30) -> 64
L32: New Eval load | M32: =M18 - M31 -> -64 | N32: =M19 - M31 -> -64
L33: Reduced time | M33: =64*20/60 -> 21.333333 | N33: =64*20/60 -> 21.333333
L34: New Time | M34: =136*20/60 -> 45.333333 | N34: =N32*20/60 -> -21.333333
K36: Threads with critical skip marked as fail - Turn 0 | L36: Count Critical Fail | M36: Count of Critical Skip
K37: =IFERROR(__xludf.DUMMYFUNCTION("UNIQUE(FILTER(evals_turn0!E:E, evals_turn0!T:T=0, evals_turn0!G:G=""fail"", evals_turn0!U:U > 0))"),"32064128:anthropic:U0ARV8X2JDU") -> 32064128:anthropic:U0ARV8X2JDU | L37: =IFERROR(__xludf.DUMMYFUNCTION("FILTER(evals_turn0!T:T, evals_turn0!T:T=0, evals_turn0!G:G=""fail"", evals_turn0!U:U > 0)"),0.0) -> 0 | M37: =IFERROR(__xludf.DUMMYFUNCTION("FILTER(evals_turn0!U:U, evals_turn0!T:T=0, evals_turn0!G:G=""fail"", evals_turn0!U:U > 0)"),1.0) -> 1
K38: =IFERROR(__xludf.DUMMYFUNCTION("""COMPUTED_VALUE"""),"28590549:google:U0ARV8X2JDU") -> 28590549:google:U0ARV8X2JDU | L38: =IFERROR(__xludf.DUMMYFUNCTION("""COMPUTED_VALUE"""),0.0) -> 0 | M38: =IFERROR(__xludf.DUMMYFUNCTION("""COMPUTED_VALUE"""),4.0) -> 4
K39: =IFERROR(__xludf.DUMMYFUNCTION("""COMPUTED_VALUE"""),"28590549:anthropic:U0ARV8X2JDU") -> 28590549:anthropic:U0ARV8X2JDU | L39: =IFERROR(__xludf.DUMMYFUNCTION("""COMPUTED_VALUE"""),0.0) -> 0 | M39: =IFERROR(__xludf.DUMMYFUNCTION("""COMPUTED_VALUE"""),4.0) -> 4
K40: =IFERROR(__xludf.DUMMYFUNCTION("""COMPUTED_VALUE"""),"36277294:anthropic:U0ARQUUJXBM") -> 36277294:anthropic:U0ARQUUJXBM | L40: =IFERROR(__xludf.DUMMYFUNCTION("""COMPUTED_VALUE"""),0.0) -> 0 | M40: =IFERROR(__xludf.DUMMYFUNCTION("""COMPUTED_VALUE"""),3.0) -> 3
K41: =IFERROR(__xludf.DUMMYFUNCTION("""COMPUTED_VALUE"""),"36277294:openai:U0ARQUUJXBM") -> 36277294:openai:U0ARQUUJXBM | L41: =IFERROR(__xludf.DUMMYFUNCTION("""COMPUTED_VALUE"""),0.0) -> 0 | M41: =IFERROR(__xludf.DUMMYFUNCTION("""COMPUTED_VALUE"""),3.0) -> 3
K42: =IFERROR(__xludf.DUMMYFUNCTION("""COMPUTED_VALUE"""),"34581102:google:U0ASRJTQSPJ") -> 34581102:google:U0ASRJTQSPJ | L42: =IFERROR(__xludf.DUMMYFUNCTION("""COMPUTED_VALUE"""),0.0) -> 0 | M42: =IFERROR(__xludf.DUMMYFUNCTION("""COMPUTED_VALUE"""),1.0) -> 1
K44: Threads with critical skip marked as fail - Turn 1 | L44: Count Critical Fail | M44: Count of Critical Skip
K45: =IFERROR(__xludf.DUMMYFUNCTION("UNIQUE(FILTER(evals_turn1!E:E, evals_turn1!T:T=0, evals_turn1!G:G=""fail"", evals_turn1!U:U > 0))"),"25506763:openai:U0ASA7SCECR") -> 25506763:openai:U0ASA7SCECR | L45: =IFERROR(__xludf.DUMMYFUNCTION("FILTER(evals_turn1!T:T, evals_turn1!T:T=0, evals_turn1!G:G=""fail"", evals_turn1!U:U > 0)"),0.0) -> 0 | M45: =IFERROR(__xludf.DUMMYFUNCTION("FILTER(evals_turn1!U:U, evals_turn1!T:T=0, evals_turn1!G:G=""fail"", evals_turn1!U:U > 0)"),5.0) -> 5
...

Sheet agent_traces
A1: job_id | B1: agent | C1: job_status | D1: initial_request | E1: agent_response:turn_0 | F1: evaluation:turn_0
A2: 23829182 | B2: anthropic | C2: up:Success | D2: job_name: Need JavaScript component: extended FAB button triggering an action menu job_description: I am looking for an experienced freelance frontend dev to create the following JavaScript component: An extended floating action button that opens an action menu on click, according to the Material specs. Extended FAB = A FAB with icon and label. Here's a description: https://material.io/components/buttons-floating-action-button/#extended-fab (see also screenshot). On click, it should overlay an action menu (like in the video/screenshot attached). Important is that the FAB can be put in the bottom right corner of the page (position fixed) and that the menu opens above the FAB, to the top. So that if you click twice (without moving the cursor), you end up clicking the last option of the action menu. The implementation should be in pure CSS, HTML and JavaScript (you can also use TypeScript and/or SCSS for styling). Colors and texts don't matter, but should be easy to change. Performance is important: it should be smoothly implemented, much like in the examples of the Material docs. It's not important to make it as a highly configurable web component. Just the HTML, CSS (and if necessary, the JavaScript/TypeScript) is needed. **NO usage of 3th party libraries or frameworks. So no jQuery, bootstrap, Material frameworks, React, etc... You can base the code of existing FAB implementations (there are some on Codepen and many other websites) if the license allows it, but the deliverable should be pure HTML+CSS(+JS) without dependencies** Thank you, looking forward to working together! | E2: # hapi-v2-benchmark Repo to collect HAPI v2 benchmark agent deliverable | F2: { "job_id": "23829182", "agent_name": "anthropic", "turn": 0, "evaluator": "U0ASA7SCECR", "overall_judgement": "pass", "submission_feedback": [ { "id": 1, "label": "critical", "judgement": "pass", "reasoning": "The index.html includes a <button class=\"fab\"> containing both a Material icon SVG and a text label \"Actions\", following the extended FAB design." }, { "id": 2, "label": "critical", "judgement": "pass", "reasoning": "The action menu is positioned within a flex container that stacks elements vertically, ensuring the fab-menu overlays directly above the FAB when opened." }, { "id": 3, "label": "critical", "judgement": "pass", "reasoning": "The implementation uses only native HTML5, CSS3 (with custom properties), and vanilla JavaScript without any external libraries or frameworks." }, { "id": 4, "label": "critical", "judgement": "pass", "reasoning": "The implementation uses only native HTML5, CSS3 (with custom properties), and vanilla JavaScript without any external libraries or frameworks." }, { "id": 5, "label": "critical", "judgement": "pass", "reasoning": "Animations use the standard Material Design cubic-bezier(0.4, 0, 0.2, 1) easing and staggered delays to provide a smooth, performant expansion effect." }, { "id": 6, "label": "optional", "judgement": "pass", "reasoning": "All primary colors, dimensions, and animation timings are defined as CSS variables in the @root selector, making them easy to modify." } ] }
A4: 23829182 | B4: google | C4: up:Success | D4: job_name: Need JavaScript component: extended FAB button triggering an action menu job_description: I am looking for an experienced freelance frontend dev to create the following JavaScript component: An extended floating action button that opens an action menu on click, according to the Material specs. Extended FAB = A FAB with icon and label. Here's a description: https://material.io/components/buttons-floating-action-button/#extended-fab (see also screenshot). On click, it should overlay an action menu (like in the video/screenshot attached). Important is that the FAB can be put in the bottom right corner of the page (position fixed) and that the menu opens above the FAB, to the top. So that if you click twice (without moving the cursor), you end up clicking the last option of the action menu. The implementation should be in pure CSS, HTML and JavaScript (you can also use TypeScript and/or SCSS for styling). Colors and texts don't matter, but should be easy to change. Performance is important: it should be smoothly implemented, much like in the examples of the Material docs. It's not important to make it as a highly configurable web component. Just the HTML, CSS (and if necessary, the JavaScript/TypeScript) is needed. **NO usage of 3th party libraries or frameworks. So no jQuery, bootstrap, Material frameworks, React, etc... You can base the code of existing FAB implementations (there are some on Codepen and many other websites) if the license allows it, but the deliverable should be pure HTML+CSS(+JS) without dependencies** Thank you, looking forward to working together! | E4: # Extended Floating Action Button (FAB) Component This project provides a pure HTML, CSS, and JavaScript implementation of an Extended Floating Action Button that opens an Action Menu, built according to the Material Design specifications. ## Features - **Pure Implementation**: Zero external dependencies, libraries, or frameworks (no jQuery, Bootstrap, React, etc.). - **Material Specs**: Uses standard Material Design sizing, elevations, typography (Roboto), and icons. - **Fixed Position**: The FAB is positioned in the bottom right corner. - **Click-to-Action Alignment**: The action menu opens above the FAB. Its bottom-right origin perfectly aligns with the FAB such that clicking the FAB and then immediately clicking again without moving the cursor will trigger the last option in the menu. - **Ripple Effect**: Includes a custom JavaScript-based Material ripple effect for both the FAB and menu items. - **Keyboard Accessibility**: Supports keyboard navigation (`Enter` / `Space` to activate, `Escape` to close, `ArrowUp` / `ArrowDown` to navigate menu items). ## Files - `index.html`: Contains the markup for the FAB and the action menu. - `styles.css`: Contains the CSS for layout, styling, animations, and shadows. - `script.js`: Contains the logic for toggling the menu, handling clicks, keyboard accessibility, and the ripple effect. ## How to Run Since this is pure HTML/CSS/JS, no build step or installation is required: 1. Open `index.html` in any modern web browser. 2. Click the extended FAB in the bottom right corner to see the menu animate in. 3. Click again to trigger the last item, or click elsewhere to close it. | F4: { "job_id": "23829182", "agent_name": "google", "turn": 0, "evaluator": "U0ASA7SCECR", "overall_judgement": "pass", "submission_feedback": [ { "id": 1, "label": "critical", "judgement": "pass", "reasoning": "The button matches Material specs with a 56px height, rounded corners, and includes both a Material icon and a text label." }, { "id": 2, "label": "critical", "judgement": "pass", "reasoning": "The menu overlays the FAB on the Z-axis and extends upwards, fulfilling the requirement for immediate selection on a second click." }, { "id": 3, "label": "critical", "judgement": "pass", "reasoning": "The FAB container is appropriately fixed at the bottom-right of the page with standard 24px offsets from the viewport edges." }, { "id": 4, "label": "critical", "judgement": "pass", "reasoning": "The project uses only pure HTML, CSS, and vanilla JavaScript without any third-party libraries or frameworks." }, { "id": 5, "label": "critical", "judgement": "pass", "reasoning": "Open/close transitions use hardware-accelerated transforms and standard Material Design cubic-bezier easing for smooth performance." }, { "id": 6, "label": "optional", "judgement": "pass", "reasoning": "Centralized CSS variables and semantic HTML structure allow for easy modification of colors and text content without touching logic." } ] }
A6: 23829182 | B6: openai | C6: up:Success | D6: job_name: Need JavaScript component: extended FAB button triggering an action menu job_description: I am looking for an experienced freelance frontend dev to create the following JavaScript component: An extended floating action button that opens an action menu on click, according to the Material specs. Extended FAB = A FAB with icon and label. Here's a description: https://material.io/components/buttons-floating-action-button/#extended-fab (see also screenshot). On click, it should overlay an action menu (like in the video/screenshot attached). Important is that the FAB can be put in the bottom right corner of the page (position fixed) and that the menu opens above the FAB, to the top. So that if you click twice (without moving the cursor), you end up clicking the last option of the action menu. The implementation should be in pure CSS, HTML and JavaScript (you can also use TypeScript and/or SCSS for styling). Colors and texts don't matter, but should be easy to change. Performance is important: it should be smoothly implemented, much like in the examples of the Material docs. It's not important to make it as a highly configurable web component. Just the HTML, CSS (and if necessary, the JavaScript/TypeScript) is needed. **NO usage of 3th party libraries or frameworks. So no jQuery, bootstrap, Material frameworks, React, etc... You can base the code of existing FAB implementations (there are some on Codepen and many other websites) if the license allows it, but the deliverable should be pure HTML+CSS(+JS) without dependencies** Thank you, looking forward to working together! | E6: # Extended FAB Action Menu This deliverable is a dependency-free implementation of an extended floating action button that opens an overlay action menu upward from the bottom-right corner of the page. ## What Was Built - A fixed extended FAB with icon and label - An upward-opening action menu anchored to the same bottom-right origin - Pure HTML, CSS, and JavaScript with no third-party libraries - Keyboard and pointer interactions for opening, closing, and selecting actions - Styling via CSS custom properties so colors and spacing are easy to change ## Files - `index.html` contains the demo markup and the component structure - `styles.css` contains all component and page styling - `script.js` contains the menu toggle and interaction logic ## Run No build step is required. 1. Open `index.html` directly in a browser. 2. Or serve the folder with a static server, for example: ```bash python3 -m http.server 8000 ``` Then visit `http://localhost:8000`. ## Customization - Update the action labels directly in `index.html` - Change colors, shadows, and sizing in the `:root` variables in `styles.css` - Move the component by editing `.fab-controller` in `styles.css` ## Behavior Notes - The menu surface is positioned from the same bottom-right anchor as the FAB - When the menu opens, it overlays the FAB so a second click without moving the pointer activates the last action - Motion uses lightweight opacity and transform transitions for smooth rendering | F6: { "job_id": "23829182", "agent_name": "openai", "turn": 0, "evaluator": "U0ASA7SCECR", "overall_judgement": "pass", "submission_feedback": [ { "id": 1, "label": "critical", "judgement": "pass", "reasoning": "The implementation includes a properly structured Extended FAB in index.html with both a SVG icon and a text label, consistent with Material Design specifications." }, { "id": 2, "label": "critical", "judgement": "pass", "reasoning": "The menu is positioned at the same anchor point as the FAB and expands upwards, ensuring the last action overlays the trigger for immediate accessibility upon a second click." }, { "id": 3, "label": "critical", "judgement": "pass", "reasoning": "The .fab-controller in styles.css uses position: fixed with clamp-based offsets to reliably anchor the component in the bottom-right corner of the viewport." }, { "id": 4, "label": "critical", "judgement": "pass", "reasoning": "The project strictly utilizes vanilla HTML, CSS (using modern features like color-mix and variables), and JavaScript without any external dependencies or frameworks" }, { "id": 5, "label": "critical", "judgement": "pass", "reasoning": "Transitions are optimized using transform and opacity properties with a custom cubic-bezier easing, resulting in a smooth, high-performance animation." }, { "id": 6, "label": "optional", "judgement": "pass", "reasoning": "A comprehensive set of CSS variables in the :root pseudo-class allows for effortless customization of the color palette, shadows, and layout dimensions." } ] }
A8: 24294313 | B8: anthropic | C8: up:Success | D8: job_name: Create a 3-page web application job_description: Create a 3-page web application in C # using ASP.NET MVC Framework. Layouts (first three attached files) DB structure (fourth file, additions / suggestions are accepted) The database can be filled with random values 1 page: The values â€‹â€‹in the table are updated with a frequency of 1 second (without reloading the page) "Time" corresponds to the value of trainingtime in the control_panel table "Position" corresponds to the value of current_position in the control_panel table "Angle" 1 corresponds to the bending value in the control_panel table "Angle" 2 corresponds to the extension value in the control_panel table "Limits" corresponds to the extension value in the control_panel table Pause 1 corresponds to the pausebending value in the control_panel table Pause 2 corresponds to the pauseextension value in the control_panel table "Speed" corresponds to the value of speed in the control_panel table 2 page: Data from the tables sens_positiondata and sens_resistancemotordata, which are updated with a frequency of 2 seconds (without reloading the page) 3 page Depending on the values â€‹â€‹of positionsel in sens_positiondata and resistdel in sens_resistancemotordata (for example, less than a certain one. It does not matter what the condition is) to output data (any, one if / esle will be enough) !!NOTE: I need web-application to be done in 2 days. | E8: # hapi-v2-benchmark Repo to collect HAPI v2 benchmark agent deliverable | F8: { "job_id": "24294313", "agent_name": "anthropic", "turn": 0, "evaluator": "U0ASA7SCECR", "overall_judgement": "pass", "submission_feedback": [ { "id": 1, "label": "critical", "judgement": "pass", "reasoning": "The application is built with the ASP.NET MVC Framework in C# and implements the required database schema using SQLite." }, { "id": 2, "label": "critical", "judgement": "pass", "reasoning": "Page 1 correctly maps and displays all required fields from the control_panel and trainingtime tables with a 1-second AJAX auto-update interval." }, { "id": 3, "label": "critical", "judgement": "pass", "reasoning": "Page 2 successfully displays data from sens_positiondata and sens_resistancemotordata in separate sections with a 2-second AJAX auto-update interval." }, { "id": 4, "label": "critical", "judgement": "pass", "reasoning": "Page 3 implements a logical condition evaluated against sensor deviations to display diagnostic messages and solutions." }, { "id": 5, "label": "critical", "judgement": "pass", "reasoning": "The visual layout and component structure (tables, sections, and navigation) align with the provided mockup images." }, { "id": 6, "label": "optional", "judgement": "pass", "reasoning": "The database is automatically initialized and pre-filled with randomized values during the first application startup." } ] }
A10: 24294313 | B10: google | C10: up:InReview | D10: job_name: Create a 3-page web application job_description: Create a 3-page web application in C # using ASP.NET MVC Framework. Layouts (first three attached files) DB structure (fourth file, additions / suggestions are accepted) The database can be filled with random values 1 page: The values â€‹â€‹in the table are updated with a frequency of 1 second (without reloading the page) "Time" corresponds to the value of trainingtime in the control_panel table "Position" corresponds to the value of current_position in the control_panel table "Angle" 1 corresponds to the bending value in the control_panel table "Angle" 2 corresponds to the extension value in the control_panel table "Limits" corresponds to the extension value in the control_panel table Pause 1 corresponds to the pausebending value in the control_panel table Pause 2 corresponds to the pauseextension value in the control_panel table "Speed" corresponds to the value of speed in the control_panel table 2 page: Data from the tables sens_positiondata and sens_resistancemotordata, which are updated with a frequency of 2 seconds (without reloading the page) 3 page Depending on the values â€‹â€‹of positionsel in sens_positiondata and resistdel in sens_resistancemotordata (for example, less than a certain one. It does not matter what the condition is) to output data (any, one if / esle will be enough) !!NOTE: I need web-application to be done in 2 days. | E10: # ASP.NET Core MVC 3-Page Web Application ## Overview This is a 3-page web application built with C# and ASP.NET Core MVC framework. It fulfills the requirements provided in the job description, using an Entity Framework Core In-Memory database filled with randomized data to simulate the dynamic behavior. ### Features * **Page 1 (Control Panel Data):** Displays live values from the `control_panel` table. The data is polled and updated on the frontend every 1 second without reloading the page. * **Page 2 (Sensor Data):** Displays live values from the `sens_positiondata` and `sens_resistancemotordata` tables. The data is polled and updated every 2 seconds without reloading the page. * **Page 3 (Condition Status):** Evaluates a simple IF/ELSE condition based on `positionsel` and `resistdel` values and outputs the result. The condition evaluation updates every 2 seconds without a page reload. ## Architecture & Implementation * **Backend:** ASP.NET Core 10.0 MVC * **Database:** Entity Framework Core with In-Memory Database (`Microsoft.EntityFrameworkCore.InMemory`) * **Data Simulation:** A Background Service (`RandomizeDataService`) runs continuously and randomizes the database values every second to simulate a live changing environment. * **Frontend Updates:** JavaScript `fetch` API is used with `setInterval` to poll the API endpoints (`/api/data/page1`, `/api/data/page2`, `/api/data/page3`) and update the HTML DOM dynamically. ## How to Run the Application ### Prerequisites * [.NET 10.0 SDK](https://dotnet.microsoft.com/en-us/download/dotnet/10.0) (or a compatible .NET SDK) installed on your machine. ### Instructions 1. Open your terminal or command prompt. 2. Navigate to the `src` folder inside the project root: ```bash cd src ``` 3. Run the application using the .NET CLI: ```bash dotnet run ``` 4. Open your web browser and navigate to the local URL provided in the console output (usually `http://localhost:5000` or `https://localhost:5001`). You can navigate between the three pages using the navigation bar at the top of the application. | F10: { "job_id": "24294313", "agent_name": "google", "turn": 0, "evaluator": "U0ASA7SCECR", "overall_judgement": "fail", "submission_feedback": [ { "id": 1, "label": "critical", "judgement": "pass", "reasoning": "The application is correctly built using the ASP.NET Core MVC framework in C# and implements the required database schema via Entity Framework Core." }, { "id": 2, "label": "critical", "judgement": "fail", "reasoning": " Page 1 uses a vertical table layout and generic labels that do not match the horizontal structure and specific headers (e.g., \"Current position\") shown in mockup 11.png." }, { "id": 3, "label": "critical", "judgement": "pass", "reasoning": "Page 2 lacks the separate sections and the ID/Time/Value columns required by mockup 2.png, displaying only single raw data points instead of a data list." }, { "id": 4, "label": "critical", "judgement": "pass", "reasoning": "Page 3 successfully implements a logical condition check on positionsel and resistdel values and updates the UI message accordingly without a page reload." }, { "id": 5, "label": "critical", "judgement": "fail", "reasoning": "The visual layout fails to match the mockups, specifically regarding the navigation bar labels (\"Page 1\" vs. \"Monitoring\") and the overall page hierarchy." }, { "id": 6, "label": "optional", "judgement": "pass", "reasoning": "The application correctly pre-fills the in-memory database with random values upon startup through a seed routine in Program.cs." } ] }
A12: 24294313 | B12: openai | C12: up:Reviewed | D12: job_name: Create a 3-page web application job_description: Create a 3-page web application in C # using ASP.NET MVC Framework. Layouts (first three attached files) DB structure (fourth file, additions / suggestions are accepted) The database can be filled with random values 1 page: The values â€‹â€‹in the table are updated with a frequency of 1 second (without reloading the page) "Time" corresponds to the value of trainingtime in the control_panel table "Position" corresponds to the value of current_position in the control_panel table "Angle" 1 corresponds to the bending value in the control_panel table "Angle" 2 corresponds to the extension value in the control_panel table "Limits" corresponds to the extension value in the control_panel table Pause 1 corresponds to the pausebending value in the control_panel table Pause 2 corresponds to the pauseextension value in the control_panel table "Speed" corresponds to the value of speed in the control_panel table 2 page: Data from the tables sens_positiondata and sens_resistancemotordata, which are updated with a frequency of 2 seconds (without reloading the page) 3 page Depending on the values â€‹â€‹of positionsel in sens_positiondata and resistdel in sens_resistancemotordata (for example, less than a certain one. It does not matter what the condition is) to output data (any, one if / esle will be enough) !!NOTE: I need web-application to be done in 2 days. | E12: # Motion Monitor ASP.NET Core MVC web application that implements the requested three-page monitoring dashboard in C#. ## What Was Built - `Home`: a control-panel summary table that refreshes every 1 second without reloading. - `Monitoring`: live position and resistance tables sourced from `sens_positiondata` and `sens_resistancemotordata`, refreshed every 2 seconds. - `Error`: a rule-based diagnostic page that evaluates `positionsel` and `resistdel` and outputs a problem, cause, and solution. - SQLite-backed persistence with seeded random telemetry and a hosted simulator that keeps the values changing while the app runs. ## Stack - .NET 8 - ASP.NET Core MVC - Entity Framework Core with SQLite - Vanilla JavaScript polling with `fetch` ## Project Structure - `src/MonitoringDashboard`: MVC application - `src/MonitoringDashboard/Data`: EF Core context and database seeding - `src/MonitoringDashboard/Services`: background telemetry simulator - `src/MonitoringDashboard/ViewModels`: page and API response models ## Run Locally ```bash dotnet restore MonitoringDashboard.slnx dotnet run --project src/MonitoringDashboard/MonitoringDashboard.csproj ``` Then open the local URL printed by ASP.NET Core. ## Notes - The original schema image was simplified into the tables required by the issue so the requested screens can map directly to persisted values. - The SQLite database file is created automatically on first run and is ignored by git. | F12: { "job_id": "24294313", "agent_name": "openai", "turn": 0, "evaluator": "U0ASA7SCECR", "overall_judgement": "pass", "submission_feedback": [ { "id": 1, "label": "critical", "judgement": "pass", "reasoning": "The application is built using the ASP.NET MVC Framework in C#, and the database models (ControlPanelState, PositionSensorReading, ResistanceMotorReading) correctly map to the specified schema tables." }, { "id": 2, "label": "critical", "judgement": "pass", "reasoning": "The Home page (Page 1) displays a summary table with values from the control_panel table, including the trainingtime mapping, and uses AJAX polling in site.js to auto-update every 1 second." }, { "id": 3, "label": "critical", "judgement": "pass", "reasoning": "The Monitoring page (Page 2) features separate sections for position and resistance sensor data, which auto-update every 2 seconds without a page reload using background fetch calls." }, { "id": 4, "label": "critical", "judgement": "pass", "reasoning": "The Error page (Page 3) implements a diagnostic logic in the HomeController that evaluates the positionsel and resistdel fields against defined thresholds to display conditional error messages." }, { "id": 5, "label": "critical", "judgement": "pass", "reasoning": "The user interface structure and telemetry table layouts in the Razor views (Index.cshtml, Monitoring.cshtml, Error.cshtml) align with the visual organization shown in the provided mockup images." }, { "id": 6, "label": "optional", "judgement": "pass", "reasoning": "The database is pre-filled during application startup by the AppDbInitializer class, which seeds the SQLite tables with initial random values for immediately functional monitoring." } ] }
A14: 24766666 | B14: anthropic | C14: up:Success | D14: job_name: Vue.js Express MEVN Google Drive API wrapper interface & Web App development job_description: Initial project which could lead to more work Mongo if needed Express for API Vue.js for UI Node.js Using token from Google drive Create a Microservice to query the list documents from Google Drive Frontend Web app will display a list of retrieved document names Tapping on a document name will display the document metadata Page can be refreshed to update list if any new documents added to Google Drive This is a very simple project. Read only access to Google drive. I am just an individual so I don't have a large budget however if you can do a good job and I get funding then the rest of the app can be built out Bonus points if you can deploy this to gcp, amazon, azure or any cloud service and have a CI pipeline with tests Bonus if design is so beautifully simple and functional on desktop and web Update 1: Express API you develop will sit in between Google and Vue.js UI One day I will point to a different document server (e.g. DropBox) or I may use a different UI. The API should be able to simply passthrough some values. List files: https://developers.google.com/drive/api/v3/reference/files/list Get file details: https://developers.google.com/drive/api/v3/reference/files#resource | E14: # hapi-v2-benchmark Repo to collect HAPI v2 benchmark agent deliverable | F14: { "job_id": "24766666", "agent_name": "anthropic", "turn": 0, "evaluator": "U0ASA7SCECR", "overall_judgement": "pass", "submission_feedback": [ { "id": 1, "label": "critical", "judgement": "pass", "reasoning": "The backend is built with Express and uses the googleapis library to authenticate via an OAuth2 refresh token flow defined in api/src/services/googleDrive.js." }, { "id": 2, "label": "critical", "judgement": "pass", "reasoning": "The /api/files endpoint in api/src/routes/files.js invokes the drive.files.list operation to fetch and return the user's document list." }, { "id": 3, "label": "critical", "judgement": "pass", "reasoning": "The frontend is a Vue 3 application that utilizes a FileList.vue component to render the names of retrieved files in a selectable list." }, { "id": 4, "label": "critical", "judgement": "pass", "reasoning": "Tapping a file name triggers the selectFile method, which fetches full metadata via the API and displays it in the FileDetail.vue component." }, { "id": 5, "label": "critical", "judgement": "pass", "reasoning": "A \"Refresh\" button is implemented in the application header (App.vue) that clears the current view and re-executes the loadFiles query." } ] }
A16: 24766666 | B16: google | C16: up:Success | D16: job_name: Vue.js Express MEVN Google Drive API wrapper interface & Web App development job_description: Initial project which could lead to more work Mongo if needed Express for API Vue.js for UI Node.js Using token from Google drive Create a Microservice to query the list documents from Google Drive Frontend Web app will display a list of retrieved document names Tapping on a document name will display the document metadata Page can be refreshed to update list if any new documents added to Google Drive This is a very simple project. Read only access to Google drive. I am just an individual so I don't have a large budget however if you can do a good job and I get funding then the rest of the app can be built out Bonus points if you can deploy this to gcp, amazon, azure or any cloud service and have a CI pipeline with tests Bonus if design is so beautifully simple and functional on desktop and web Update 1: Express API you develop will sit in between Google and Vue.js UI One day I will point to a different document server (e.g. DropBox) or I may use a different UI. The API should be able to simply passthrough some values. List files: https://developers.google.com/drive/api/v3/reference/files/list Get file details: https://developers.google.com/drive/api/v3/reference/files#resource | E16: # Google Drive Explorer A simple MEVN stack (Vue.js, Express, Node.js) application that interfaces with the Google Drive API to list documents and view their metadata. ## Architecture This project is separated into two parts: 1. **Frontend:** A Vue.js 3 single-page application built with Vite and styled with Tailwind CSS. 2. **Backend:** An Express Node.js microservice acting as a passthrough API wrapper for the Google Drive API. The frontend sends the Google Access Token to the backend, which securely forwards requests to the Google Drive API (`v3/files`), ensuring the API acts as an abstraction layer for potential future integration with other storage providers like Dropbox. ## Prerequisites - Node.js (v16+ recommended) - A valid Google Drive API Access Token (to be pasted into the application UI). ## Quick Start ### 1. Backend Setup 1. Navigate to the backend directory: ```bash cd backend ``` 2. Install dependencies: ```bash npm install ``` 3. Start the server (runs on `http://localhost:3000` by default): ```bash npm start ``` ### 2. Frontend Setup 1. Open a new terminal and navigate to the frontend directory: ```bash cd frontend ``` 2. Install dependencies: ```bash npm install ``` 3. Start the Vite development server: ```bash npm run dev ``` 4. Open the displayed local URL in your browser (usually `http://localhost:5173`). ### Usage - In the top right corner of the UI, enter a valid Google Drive Access Token. - The app will automatically fetch and display your Google Drive documents. - Click "Refresh" at any time to sync newly added files. - Click on any document to view its detailed metadata. ## Testing Both the backend and frontend have unit tests included. **Run Backend Tests:** ```bash cd backend npm test ``` *Uses Jest and Supertest to mock HTTP requests.* **Run Frontend Tests:** ```bash cd frontend npm test ``` *Uses Vitest and Vue Test Utils for component testing.* ## Deployment Note (Bonus) Although no specific cloud provider credentials were provided, the app is structured to be easily deployed: - **Backend:** Can be deployed to Heroku, Google Cloud Run, AWS App Runner, or Azure App Service. Just ensure the `PORT` environment variable is respected (already handled in `server.js`). - **Frontend:** Can be built using `npm run build` and the resulting `dist/` directory deployed to Vercel, Netlify, GitHub Pages, or AWS S3. You may need to provide `VITE_API_URL` during build time to point to the deployed backend URL. | F16: { "job_id": "24766666", "agent_name": "google", "turn": 0, "evaluator": "U0ASA7SCECR", "overall_judgement": "pass", "submission_feedback": [ { "id": 1, "label": "critical", "judgement": "pass", "reasoning": "The backend is built with Node.js and Express, implementing a mechanism to authenticate requests to Google Drive using a provided bearer token." }, { "id": 2, "label": "critical", "judgement": "pass", "reasoning": "The API includes a /api/files endpoint that successfully executes the Google Drive files.list operation to retrieve and return a list of files." }, { "id": 3, "label": "critical", "judgement": "pass", "reasoning": "The frontend is a Vue.js application that renders a list of Google Drive document names within the HomeView.vue component." }, { "id": 4, "label": "critical", "judgement": "pass", "reasoning": "Selecting a document navigates to the FileDetailsView.vue page, which fetches and displays detailed metadata via the Google Drive file details resource." }, { "id": 5, "label": "critical", "judgement": "pass", "reasoning": "The UI includes a dedicated \"Refresh\" button in the HomeView that re-queries the backend to update the displayed list of documents." } ] }
A18: 24766666 | B18: openai | C18: up:Reviewed | D18: job_name: Vue.js Express MEVN Google Drive API wrapper interface & Web App development job_description: Initial project which could lead to more work Mongo if needed Express for API Vue.js for UI Node.js Using token from Google drive Create a Microservice to query the list documents from Google Drive Frontend Web app will display a list of retrieved document names Tapping on a document name will display the document metadata Page can be refreshed to update list if any new documents added to Google Drive This is a very simple project. Read only access to Google drive. I am just an individual so I don't have a large budget however if you can do a good job and I get funding then the rest of the app can be built out Bonus points if you can deploy this to gcp, amazon, azure or any cloud service and have a CI pipeline with tests Bonus if design is so beautifully simple and functional on desktop and web Update 1: Express API you develop will sit in between Google and Vue.js UI One day I will point to a different document server (e.g. DropBox) or I may use a different UI. The API should be able to simply passthrough some values. List files: https://developers.google.com/drive/api/v3/reference/files/list Get file details: https://developers.google.com/drive/api/v3/reference/files#resource | E18: # Google Drive Document Browser A small full-stack application that wraps the Google Drive Files API with an Express microservice and presents the results in a responsive Vue interface. ## What was built - An Express API that sits between Google Drive and the UI. - A provider-based backend structure so the document source can be swapped later. - A Vue single-page app that lists documents, refreshes on demand, and shows metadata for the selected file. - Automated backend tests for the API and Google Drive provider behavior. ## Project structure - `server/` - Express API and Google Drive provider - `src/` - Vue frontend - `index.html` - Vite entry document - `.env.example` - required environment variables ## API endpoints ### `GET /api/health` Returns a simple health response. ### `GET /api/documents` Lists Google Drive files. Supported passthrough query parameters: - `corpora` - `driveId` - `fields` - `includeItemsFromAllDrives` - `orderBy` - `pageSize` - `pageToken` - `q` - `spaces` - `supportsAllDrives` Response includes: - `documents` - normalized document list for the UI - `nextPageToken` - raw pagination token from Google Drive - `query` - effective upstream query used by the provider - `raw` - raw Google Drive API payload ### `GET /api/documents/:documentId` Returns normalized metadata plus the raw Google Drive file resource. Supported passthrough query parameters: - `fields` - `supportsAllDrives` ## Environment Create a `.env` file with: ```bash PORT=3000 GOOGLE_DRIVE_TOKEN=your_google_drive_bearer_token GOOGLE_DRIVE_API_BASE_URL=https://www.googleapis.com/drive/v3 ``` ## Install and run ```bash npm install npm run dev ``` This starts: - Express API on `http://localhost:3000` - Vue dev server on `http://localhost:5173` ## Production build ```bash npm run build npm start ``` The server will serve the built Vue app from `dist/` when present. ## Test ```bash npm test ``` ## Notes - The API uses read-only Google Drive access via a bearer token. - The backend normalizes document data for the current UI, while also returning raw upstream payloads for future consumers. - The frontend is designed to work on desktop and mobile, with a layout inspired by the supplied mockup. | F18: { "job_id": "24766666", "agent_name": "openai", "turn": 0, "evaluator": "U0ASA7SCECR", "overall_judgement": "pass", "submission_feedback": [ { "id": 1, "label": "critical", "judgement": "pass", "reasoning": "The backend is a standard Node.js + Express microservice that correctly uses a Bearer token for Google Drive API authentication." }, { "id": 2, "label": "critical", "judgement": "pass", "reasoning": "An Express route /api/documents is implemented that utilizes the Google Drive files.list operation to fetch document data." }, { "id": 3, "label": "critical", "judgement": "pass", "reasoning": "The frontend is a Vue.js application that successfully maps and displays document names in a structured list." }, { "id": 4, "label": "critical", "judgement": "pass", "reasoning": "The UI includes logic to fetch and display detailed metadata (size, type, owner, etc.) when a document is selected from the list." }, { "id": 5, "label": "critical", "judgement": "pass", "reasoning": "A dedicated \"Refresh\" button is provided in the UI header to re-query the API and update the file listing.\n" } ] }
A20: 25034870 | B20: anthropic | C20: up:Reviewed | D20: job_name: Need a company portfolio SPA dynamic web using vuejs,lumen. job_description: Hello, We are renown IT firm. We have a simple portfolio site (https://theworld.com.bd/). But we now want to furnish it or start from scratch. For that you will suggest us few simple and lucrative portfolio design sample you did before. Sample: https://bootstrapmade.com/demo/themes/Mamba/ Then you will do front-end and back-end by yourself. We want to use vuejs SPA (https://chaldal.com) and laravel lumen for API and mysql or any other DB you know well. You can use any css framework(bootstrap 4, ) compatible with vuejs, we can discuss about it later. For now we need Home page (slide show+client review, project), About Us, Service,Portfolio,Team, Gallery image, Contact Us page with strong structural back-end as we will continue the application with more feature like employee payroll and login and so on. Public section: Home page with lucrative slide show,Contact Us, Portfolio, Clients, Service live facebook like and other few pages, a portfolio site has. Admin Section: For now back-end must be strong using lumen api. One user may have multiple rules. All publicly visible pages must be from admin set up, means dynamic. Milestone:$40+$40+$20 (fron-end+back-end+finalize all errors) If you do well then we may continue with hourly basis for more of those features. | E20: # TheWorld IT Firm — Portfolio SPA (Job 25034870) A complete company portfolio web application built with Vue.js 3 SPA frontend and Laravel Lumen REST API backend, as requested. See [`deliverable/README.md`](./deliverable/README.md) for full documentation, installation instructions, and API reference. ## Quick Summary - **Frontend:** Vue.js 3 + Bootstrap 5 SPA with 10+ public pages and full admin panel - **Backend:** Laravel Lumen 10 REST API with JWT auth, multi-role RBAC, and 14 database tables - **All public content is dynamic**, managed through the admin panel | F20: { "job_id": "25034870", "agent_name": "anthropic", "turn": 0, "evaluator": "U0ASA7SCECR", "overall_judgement": "fail", "submission_feedback": [ { "id": 1, "label": "critical", "judgement": "pass", "reasoning": "The project includes Home, About Us, Projects, Blog, and Contact Us pages implemented with a design style following the Porto template." }, { "id": 2, "label": "critical", "judgement": "fail", "reasoning": "The Home page slider includes navigation and content buttons, while the project sections are missing the required social sharing functionality." }, { "id": 3, "label": "critical", "judgement": "fail", "reasoning": "The team section does not link owner details to the specified 'about-me' reference page as required." }, { "id": 4, "label": "critical", "judgement": "fail", "reasoning": "The footer is missing the membership logo, and the subscription area is not correctly positioned according to the criteria." }, { "id": 5, "label": "critical", "judgement": "fail", "reasoning": " The layout follows a fluid full-width structure instead of the mandatory boxed layout specified in the requirements." } ] }
A22: 25034870 | B22: google | C22: up:InReview | D22: job_name: Need a company portfolio SPA dynamic web using vuejs,lumen. job_description: Hello, We are renown IT firm. We have a simple portfolio site (https://theworld.com.bd/). But we now want to furnish it or start from scratch. For that you will suggest us few simple and lucrative portfolio design sample you did before. Sample: https://bootstrapmade.com/demo/themes/Mamba/ Then you will do front-end and back-end by yourself. We want to use vuejs SPA (https://chaldal.com) and laravel lumen for API and mysql or any other DB you know well. You can use any css framework(bootstrap 4, ) compatible with vuejs, we can discuss about it later. For now we need Home page (slide show+client review, project), About Us, Service,Portfolio,Team, Gallery image, Contact Us page with strong structural back-end as we will continue the application with more feature like employee payroll and login and so on. Public section: Home page with lucrative slide show,Contact Us, Portfolio, Clients, Service live facebook like and other few pages, a portfolio site has. Admin Section: For now back-end must be strong using lumen api. One user may have multiple rules. All publicly visible pages must be from admin set up, means dynamic. Milestone:$40+$40+$20 (fron-end+back-end+finalize all errors) If you do well then we may continue with hourly basis for more of those features. | E22: # TheWorld Portfolio App This project consists of two separate applications: 1. **Frontend**: A Vue.js 3 SPA with Vue Router, Tailwind CSS 3, and Axios. 2. **Backend**: A Laravel Lumen API with a pre-configured SQLite database. ## Prerequisites - Node.js (v16+) - PHP (v8.1+) - Composer ## Getting Started ### 1. Backend Setup (Lumen API) Open a terminal and navigate to the `backend` directory. ```bash cd backend # Install dependencies composer install # Set up the SQLite database and seed it with dummy data touch database/database.sqlite php artisan migrate php artisan db:seed # Start the API server php -S localhost:8000 -t public ``` The API will be available at `http://localhost:8000/api`. ### 2. Frontend Setup (Vue SPA) Open another terminal and navigate to the `frontend` directory. ```bash cd frontend # Install dependencies npm install # Start the development server npm run dev ``` The frontend will be accessible at `http://localhost:5173/` (or whichever port Vite uses). ## Features - **Public Portfolio**: A complete one-page layout covering the Home slider, About Us, Services, Portfolio (projects), Team, Client Testimonials, and a Contact form. - **Admin Section**: A protected dashboard for managing data (CRUD operations on Slides, Services, Projects, Team, etc.). Access it via the `/admin` route. - **Login Credentials**: - Email: `admin@example.com` - Password: `password` ## Design & Architecture - **Vue.js**: Leverages Vue 3 Composition API for reactive components. - **Tailwind CSS**: A utility-first CSS framework for a responsive, modern "lucrative" layout. - **Lumen**: A micro-framework by Laravel optimized for APIs, making it incredibly fast. - **SQLite**: Used for easy out-of-the-box development and testing without needing a standalone MySQL server running. | F22: { "job_id": "25034870", "agent_name": "google", "turn": 0, "evaluator": "U0ASA7SCECR", "overall_judgement": "fail", "submission_feedback": [ { "id": 1, "label": "critical", "judgement": "fail", "reasoning": "Only the Home and Admin pages are implemented as routes; separate pages for About Us, Projects, Blog, and Contact Us using the Porto template are missing." }, { "id": 2, "label": "critical", "judgement": "fail", "reasoning": "The slider includes navigation buttons (contrary to \"without buttons\"), and required elements like client count and social sharing for projects are not present." }, { "id": 3, "label": "critical", "judgement": "fail", "reasoning": "The team section does not differentiate between Owner and Employees, and there is no link provided for the owner to an 'about-me' reference page." }, { "id": 4, "label": "critical", "judgement": "fail", "reasoning": "The footer is missing the latest blog section, the subscription area, and several specific menu links required by the criteria." }, { "id": 5, "label": "critical", "judgement": "fail", "reasoning": "The layout uses a standard container approach rather than the specific Porto-style boxed structure referenced in the instructions." } ] }
